Workbook

Sheet สรุปยานพาหนะ 67-70 (2)
A1: สถิติงบลงทุน 3 ปีย้อนหลัง (2567-2570) (ประเภท ยานพาหนะและขนส่ง)
A3: จังหวัด | B3: หน่วยงานที่ขอ | C3: พรบ. 67 | F3: พรบ. 68 | I3: พรบ. 69 | L3: คำขอ 70
C4: ครุภัณฑ์ | D4: จำนวน | E4: รวม | F4: ครุภัณฑ์ | G4: จำนวน | H4: รวม | I4: ครุภัณฑ์ | J4: จำนวน | K4: รวม | L4: ครุภัณฑ์ | M4: จำนวน (ขอทดแทน) | N4: จำนวน (เพิ่มประสิทธิภาพ) | O4: จำนวน (รวมคำขอทั้งสิ้น) | P4: รวม
A5: ภาคเหนือ
A6: เชียงราย | B6: พมจ.เชียงราย | C6: =SUMIFS('ครุภัณฑ์ 67'!G:G,'ครุภัณฑ์ 67'!C:C,"ยานพาหนะและขนส่ง",'ครุภัณฑ์ 67'!E:E,B6) -> 0 | D6: =SUMIFS('ครุภัณฑ์ 67'!F:F,'ครุภัณฑ์ 67'!C:C,"ยานพาหนะและขนส่ง",'ครุภัณฑ์ 67'!E:E,B6) -> 0 | E6: =C6:C17 -> 0 | F6: =SUMIFS('ครุภัณฑ์ 68'!G:G,'ครุภัณฑ์ 68'!C:C,"ยานพาหนะและขนส่ง",'ครุภัณฑ์ 68'!E:E,B6) -> 0 | G6: =SUMIFS('ครุภัณฑ์ 68'!F:F,'ครุภัณฑ์ 68'!C:C,"ยานพาหนะและขนส่ง",'ครุภัณฑ์ 68'!E:E,B6) -> 0 | H6: =F6 -> 0 | I6: =SUMIFS('ครุภัณฑ์ 69'!G:G,'ครุภัณฑ์ 69'!C:C,"ยานพาหนะและขนส่ง",'ครุภัณฑ์ 69'!E:E,B6) -> 0 | J6: =SUMIFS('ครุภัณฑ์ 69'!F:F,'ครุภัณฑ์ 69'!C:C,"ยานพาหนะและขนส่ง",'ครุภัณฑ์ 69'!E:E,B6) -> 0 | K6: =I6 -> 0 | L6: =SUMIFS('รวมครุภัณฑ์ 70'!L:L,'รวมครุภัณฑ์ 70'!C:C,"ครุภัณฑ์ยานพาหนะและขนส่ง",'รวมครุภัณฑ์ 70'!H:H,B6) -> 1207900 | M6: =SUMIFS('รวมครุภัณฑ์ 70'!Q:Q,'รวมครุภัณฑ์ 70'!C:C,"ครุภัณฑ์ยานพาหนะและขนส่ง",'รวมครุภัณฑ์ 70'!H:H,B6) -> 1 | N6: =SUMIFS('รวมครุภัณฑ์ 70'!R:R,'รวมครุภัณฑ์ 70'!C:C,"ครุภัณฑ์ยานพาหนะและขนส่ง",'รวมครุภัณฑ์ 70'!H:H,B6) -> 0 | O6: =M6+N6 -> 1 | P6: =L6 -> 1207900 | Q6: =SUM(L6:L17) -> 13982300
A7: เชียงราย | B7: สคม.เชียงราย | C7: =SUMIFS('ครุภัณฑ์ 67'!G:G,'ครุภัณฑ์ 67'!C:C,"ยานพาหนะและขนส่ง",'ครุภัณฑ์ 67'!E:E,B7) -> 0 | D7: =SUMIFS('ครุภัณฑ์ 67'!F:F,'ครุภัณฑ์ 67'!C:C,"ยานพาหนะและขนส่ง",'ครุภัณฑ์ 67'!E:E,B7) -> 0 | E7: =C7:C18 -> 0 | F7: =SUMIFS('ครุภัณฑ์ 68'!G:G,'ครุภัณฑ์ 68'!C:C,"ยานพาหนะและขนส่ง",'ครุภัณฑ์ 68'!E:E,B7) -> 0 | G7: =SUMIFS('ครุภัณฑ์ 68'!F:F,'ครุภัณฑ์ 68'!C:C,"ยานพาหนะและขนส่ง",'ครุภัณฑ์ 68'!E:E,B7) -> 0 | H7: =F7 -> 0 | I7: =SUMIFS('ครุภัณฑ์ 69'!G:G,'ครุภัณฑ์ 69'!C:C,"ยานพาหนะและขนส่ง",'ครุภัณฑ์ 69'!E:E,B7) -> 0 | J7: =SUMIFS('ครุภัณฑ์ 69'!F:F,'ครุภัณฑ์ 69'!C:C,"ยานพาหนะและขนส่ง",'ครุภัณฑ์ 69'!E:E,B7) -> 0 | K7: =I7 -> 0 | L7: =SUMIFS('รวมครุภัณฑ์ 70'!L:L,'รวมครุภัณฑ์ 70'!C:C,"ครุภัณฑ์ยานพาหนะและขนส่ง",'รวมครุภัณฑ์ 70'!H:H,B7) -> 2707900 | M7: =SUMIFS('รวมครุภัณฑ์ 70'!Q:Q,'รวมครุภัณฑ์ 70'!C:C,"ครุภัณฑ์ยานพาหนะและขนส่ง",'รวมครุภัณฑ์ 70'!H:H,B7) -> 2 | N7: =SUMIFS('รวมครุภัณฑ์ 70'!R:R,'รวมครุภัณฑ์ 70'!C:C,"ครุภัณฑ์ยานพาหนะและขนส่ง",'รวมครุภัณฑ์ 70'!H:H,B7) -> 0 | O7: =M7+N7 -> 2 | P7: =L7 -> 2707900 | Q7: =SUM(#REF!) -> #REF!
A8: เชียงใหม่ | B8: สสว.9 | C8: =SUMIFS('ครุภัณฑ์ 67'!G:G,'ครุภัณฑ์ 67'!C:C,"ยานพาหนะและขนส่ง",'ครุภัณฑ์ 67'!E:E,B8) -> 2448900 | D8: =SUMIFS('ครุภัณฑ์ 67'!F:F,'ครุภัณฑ์ 67'!C:C,"ยานพาหนะและขนส่ง",'ครุภัณฑ์ 67'!E:E,B8) -> 2 | E8: =C8:C19 -> 2448900 | F8: =SUMIFS('ครุภัณฑ์ 68'!G:G,'ครุภัณฑ์ 68'!C:C,"ยานพาหนะและขนส่ง",'ครุภัณฑ์ 68'!E:E,B8) -> 0 | G8: =SUMIFS('ครุภัณฑ์ 68'!F:F,'ครุภัณฑ์ 68'!C:C,"ยานพาหนะและขนส่ง",'ครุภัณฑ์ 68'!E:E,B8) -> 0 | H8: =F8 -> 0 | I8: =SUMIFS('ครุภัณฑ์ 69'!G:G,'ครุภัณฑ์ 69'!C:C,"ยานพาหนะและขนส่ง",'ครุภัณฑ์ 69'!E:E,B8) -> 0 | J8: =SUMIFS('ครุภัณฑ์ 69'!F:F,'ครุภัณฑ์ 69'!C:C,"ยานพาหนะและขนส่ง",'ครุภัณฑ์ 69'!E:E,B8) -> 0 | K8: =I8 -> 0 | L8: =SUMIFS('รวมครุภัณฑ์ 70'!L:L,'รวมครุภัณฑ์ 70'!C:C,"ครุภัณฑ์ยานพาหนะและขนส่ง",'รวมครุภัณฑ์ 70'!H:H,B8) -> 0 | M8: =SUMIFS('รวมครุภัณฑ์ 70'!Q:Q,'รวมครุภัณฑ์ 70'!C:C,"ครุภัณฑ์ยานพาหนะและขนส่ง",'รวมครุภัณฑ์ 70'!H:H,B8) -> 0 | N8: =SUMIFS('รวมครุภัณฑ์ 70'!R:R,'รวมครุภัณฑ์ 70'!C:C,"ครุภัณฑ์ยานพาหนะและขนส่ง",'รวมครุภัณฑ์ 70'!H:H,B8) -> 0 | O8: =M8+N8 -> 0 | P8: =L8 -> 0 | Q8: =SUM(P6:P17) -> 13982300
A9: เชียงใหม่ | B9: พมจ.เชียงใหม่ | C9: =SUMIFS('ครุภัณฑ์ 67'!G:G,'ครุภัณฑ์ 67'!C:C,"ยานพาหนะและขนส่ง",'ครุภัณฑ์ 67'!E:E,B9) -> 0 | D9: =SUMIFS('ครุภัณฑ์ 67'!F:F,'ครุภัณฑ์ 67'!C:C,"ยานพาหนะและขนส่ง",'ครุภัณฑ์ 67'!E:E,B9) -> 0 | E9: - | F9: =SUMIFS('ครุภัณฑ์ 68'!G:G,'ครุภัณฑ์ 68'!C:C,"ยานพาหนะและขนส่ง",'ครุภัณฑ์ 68'!E:E,B9) -> 1358000 | G9: =SUMIFS('ครุภัณฑ์ 68'!F:F,'ครุภัณฑ์ 68'!C:C,"ยานพาหนะและขนส่ง",'ครุภัณฑ์ 68'!E:E,B9) -> 1 | H9: =F9 -> 1358000 | I9: =SUMIFS('ครุภัณฑ์ 69'!G:G,'ครุภัณฑ์ 69'!C:C,"ยานพาหนะและขนส่ง",'ครุภัณฑ์ 69'!E:E,B9) -> 0 | J9: =SUMIFS('ครุภัณฑ์ 69'!F:F,'ครุภัณฑ์ 69'!C:C,"ยานพาหนะและขนส่ง",'ครุภัณฑ์ 69'!E:E,B9) -> 0 | K9: =I9 -> 0 | L9: =SUMIFS('รวมครุภัณฑ์ 70'!L:L,'รวมครุภัณฑ์ 70'!C:C,"ครุภัณฑ์ยานพาหนะและขนส่ง",'รวมครุภัณฑ์ 70'!H:H,B9) -> 1207900 | M9: =SUMIFS('รวมครุภัณฑ์ 70'!Q:Q,'รวมครุภัณฑ์ 70'!C:C,"ครุภัณฑ์ยานพาหนะและขนส่ง",'รวมครุภัณฑ์ 70'!H:H,B9) -> 1 | N9: =SUMIFS('รวมครุภัณฑ์ 70'!R:R,'รวมครุภัณฑ์ 70'!C:C,"ครุภัณฑ์ยานพาหนะและขนส่ง",'รวมครุภัณฑ์ 70'!H:H,B9) -> 0 | O9: =M9+N9 -> 1 | P9: =L9 -> 1207900
A10: น่าน | B10: พมจ.น่าน | C10: =SUMIFS('ครุภัณฑ์ 67'!G:G,'ครุภัณฑ์ 67'!C:C,"ยานพาหนะและขนส่ง",'ครุภัณฑ์ 67'!E:E,B10) -> 1358000 | D10: =SUMIFS('ครุภัณฑ์ 67'!F:F,'ครุภัณฑ์ 67'!C:C,"ยานพาหนะและขนส่ง",'ครุภัณฑ์ 67'!E:E,B10) -> 1 | E10: =C10:C21 -> 1358000 | F10: =SUMIFS('ครุภัณฑ์ 68'!G:G,'ครุภัณฑ์ 68'!C:C,"ยานพาหนะและขนส่ง",'ครุภัณฑ์ 68'!E:E,B10) -> 0 | G10: =SUMIFS('ครุภัณฑ์ 68'!F:F,'ครุภัณฑ์ 68'!C:C,"ยานพาหนะและขนส่ง",'ครุภัณฑ์ 68'!E:E,B10) -> 0 | H10: =F10 -> 0 | I10: =SUMIFS('ครุภัณฑ์ 69'!G:G,'ครุภัณฑ์ 69'!C:C,"ยานพาหนะและขนส่ง",'ครุภัณฑ์ 69'!E:E,B10) -> 0 | J10: =SUMIFS('ครุภัณฑ์ 69'!F:F,'ครุภัณฑ์ 69'!C:C,"ยานพาหนะและขนส่ง",'ครุภัณฑ์ 69'!E:E,B10) -> 0 | K10: =I10 -> 0 | L10: =SUMIFS('รวมครุภัณฑ์ 70'!L:L,'รวมครุภัณฑ์ 70'!C:C,"ครุภัณฑ์ยานพาหนะและขนส่ง",'รวมครุภัณฑ์ 70'!H:H,B10) -> 1207900 | M10: =SUMIFS('รวมครุภัณฑ์ 70'!Q:Q,'รวมครุภัณฑ์ 70'!C:C,"ครุภัณฑ์ยานพาหนะและขนส่ง",'รวมครุภัณฑ์ 70'!H:H,B10) -> 1 | N10: =SUMIFS('รวมครุภัณฑ์ 70'!R:R,'รวมครุภัณฑ์ 70'!C:C,"ครุภัณฑ์ยานพาหนะและขนส่ง",'รวมครุภัณฑ์ 70'!H:H,B10) -> 0 | O10: =M10+N10 -> 1 | P10: =L10 -> 1207900
A11: พะเยา | B11: พมจ.พะเยา | C11: =SUMIFS('ครุภัณฑ์ 67'!G:G,'ครุภัณฑ์ 67'!C:C,"ยานพาหนะและขนส่ง",'ครุภัณฑ์ 67'!E:E,B11) -> 0 | D11: =SUMIFS('ครุภัณฑ์ 67'!F:F,'ครุภัณฑ์ 67'!C:C,"ยานพาหนะและขนส่ง",'ครุภัณฑ์ 67'!E:E,B11) -> 0 | E11: =C11:C22 -> 0 | F11: =SUMIFS('ครุภัณฑ์ 68'!G:G,'ครุภัณฑ์ 68'!C:C,"ยานพาหนะและขนส่ง",'ครุภัณฑ์ 68'!E:E,B11) -> 0 | G11: =SUMIFS('ครุภัณฑ์ 68'!F:F,'ครุภัณฑ์ 68'!C:C,"ยานพาหนะและขนส่ง",'ครุภัณฑ์ 68'!E:E,B11) -> 0 | H11: =F11 -> 0 | I11: =SUMIFS('ครุภัณฑ์ 69'!G:G,'ครุภัณฑ์ 69'!C:C,"ยานพาหนะและขนส่ง",'ครุภัณฑ์ 69'!E:E,B11) -> 0 | J11: =SUMIFS('ครุภัณฑ์ 69'!F:F,'ครุภัณฑ์ 69'!C:C,"ยานพาหนะและขนส่ง",'ครุภัณฑ์ 69'!E:E,B11) -> 0 | K11: =I11 -> 0 | L11: =SUMIFS('รวมครุภัณฑ์ 70'!L:L,'รวมครุภัณฑ์ 70'!C:C,"ครุภัณฑ์ยานพาหนะและขนส่ง",'รวมครุภัณฑ์ 70'!H:H,B11) -> 0 | M11: =SUMIFS('รวมครุภัณฑ์ 70'!Q:Q,'รวมครุภัณฑ์ 70'!C:C,"ครุภัณฑ์ยานพาหนะและขนส่ง",'รวมครุภัณฑ์ 70'!H:H,B11) -> 0 | N11: =SUMIFS('รวมครุภัณฑ์ 70'!R:R,'รวมครุภัณฑ์ 70'!C:C,"ครุภัณฑ์ยานพาหนะและขนส่ง",'รวมครุภัณฑ์ 70'!H:H,B11) -> 0 | O11: =M11+N11 -> 0 | P11: =L11 -> 0
A12: แพร่ | B12: พมจ.แพร่ | C12: =SUMIFS('ครุภัณฑ์ 67'!G:G,'ครุภัณฑ์ 67'!C:C,"ยานพาหนะและขนส่ง",'ครุภัณฑ์ 67'!E:E,B12) -> 0 | D12: =SUMIFS('ครุภัณฑ์ 67'!F:F,'ครุภัณฑ์ 67'!C:C,"ยานพาหนะและขนส่ง",'ครุภัณฑ์ 67'!E:E,B12) -> 0 | E12: =C12:C23 -> 0 | F12: =SUMIFS('ครุภัณฑ์ 68'!G:G,'ครุภัณฑ์ 68'!C:C,"ยานพาหนะและขนส่ง",'ครุภัณฑ์ 68'!E:E,B12) -> 885900 | G12: =SUMIFS('ครุภัณฑ์ 68'!F:F,'ครุภัณฑ์ 68'!C:C,"ยานพาหนะและขนส่ง",'ครุภัณฑ์ 68'!E:E,B12) -> 1 | H12: =F12 -> 885900 | I12: =SUMIFS('ครุภัณฑ์ 69'!G:G,'ครุภัณฑ์ 69'!C:C,"ยานพาหนะและขนส่ง",'ครุภัณฑ์ 69'!E:E,B12) -> 0 | J12: =SUMIFS('ครุภัณฑ์ 69'!F:F,'ครุภัณฑ์ 69'!C:C,"ยานพาหนะและขนส่ง",'ครุภัณฑ์ 69'!E:E,B12) -> 0 | K12: =I12 -> 0 | L12: =SUMIFS('รวมครุภัณฑ์ 70'!L:L,'รวมครุภัณฑ์ 70'!C:C,"ครุภัณฑ์ยานพาหนะและขนส่ง",'รวมครุภัณฑ์ 70'!H:H,B12) -> 0 | M12: =SUMIFS('รวมครุภัณฑ์ 70'!Q:Q,'รวมครุภัณฑ์ 70'!C:C,"ครุภัณฑ์ยานพาหนะและขนส่ง",'รวมครุภัณฑ์ 70'!H:H,B12) -> 0 | N12: =SUMIFS('รวมครุภัณฑ์ 70'!R:R,'รวมครุภัณฑ์ 70'!C:C,"ครุภัณฑ์ยานพาหนะและขนส่ง",'รวมครุภัณฑ์ 70'!H:H,B12) -> 0 | O12: =M12+N12 -> 0 | P12: =L12 -> 0
A13: แม่ฮ่องสอน | B13: พมจ.แม่ฮ่องสอน | C13: =SUMIFS('ครุภัณฑ์ 67'!G:G,'ครุภัณฑ์ 67'!C:C,"ยานพาหนะและขนส่ง",'ครุภัณฑ์ 67'!E:E,B13) -> 0 | D13: =SUMIFS('ครุภัณฑ์ 67'!F:F,'ครุภัณฑ์ 67'!C:C,"ยานพาหนะและขนส่ง",'ครุภัณฑ์ 67'!E:E,B13) -> 0 | E13: =C13:C24 -> 0 | F13: =SUMIFS('ครุภัณฑ์ 68'!G:G,'ครุภัณฑ์ 68'!C:C,"ยานพาหนะและขนส่ง",'ครุภัณฑ์ 68'!E:E,B13) -> 1090900 | G13: =SUMIFS('ครุภัณฑ์ 68'!F:F,'ครุภัณฑ์ 68'!C:C,"ยานพาหนะและขนส่ง",'ครุภัณฑ์ 68'!E:E,B13) -> 1 | H13: =F13 -> 1090900 | I13: =SUMIFS('ครุภัณฑ์ 69'!G:G,'ครุภัณฑ์ 69'!C:C,"ยานพาหนะและขนส่ง",'ครุภัณฑ์ 69'!E:E,B13) -> 1369000 | J13: =SUMIFS('ครุภัณฑ์ 69'!F:F,'ครุภัณฑ์ 69'!C:C,"ยานพาหนะและขนส่ง",'ครุภัณฑ์ 69'!E:E,B13) -> 1 | K13: =I13 -> 1369000 | L13: =SUMIFS('รวมครุภัณฑ์ 70'!L:L,'รวมครุภัณฑ์ 70'!C:C,"ครุภัณฑ์ยานพาหนะและขนส่ง",'รวมครุภัณฑ์ 70'!H:H,B13) -> 1268000 | M13: =SUMIFS('รวมครุภัณฑ์ 70'!Q:Q,'รวมครุภัณฑ์ 70'!C:C,"ครุภัณฑ์ยานพาหนะและขนส่ง",'รวมครุภัณฑ์ 70'!H:H,B13) -> 2 | N13: =SUMIFS('รวมครุภัณฑ์ 70'!R:R,'รวมครุภัณฑ์ 70'!C:C,"ครุภัณฑ์ยานพาหนะและขนส่ง",'รวมครุภัณฑ์ 70'!H:H,B13) -> 0 | O13: =M13+N13 -> 2 | P13: =L13 -> 1268000
A14: ลำปาง | B14: พมจ.ลำปาง | C14: =SUMIFS('ครุภัณฑ์ 67'!G:G,'ครุภัณฑ์ 67'!C:C,"ยานพาหนะและขนส่ง",'ครุภัณฑ์ 67'!E:E,B14) -> 0 | D14: =SUMIFS('ครุภัณฑ์ 67'!F:F,'ครุภัณฑ์ 67'!C:C,"ยานพาหนะและขนส่ง",'ครุภัณฑ์ 67'!E:E,B14) -> 0 | E14: =C14:C25 -> 0 | F14: =SUMIFS('ครุภัณฑ์ 68'!G:G,'ครุภัณฑ์ 68'!C:C,"ยานพาหนะและขนส่ง",'ครุภัณฑ์ 68'!E:E,B14) -> 1358000 | G14: =SUMIFS('ครุภัณฑ์ 68'!F:F,'ครุภัณฑ์ 68'!C:C,"ยานพาหนะและขนส่ง",'ครุภัณฑ์ 68'!E:E,B14) -> 1 | H14: =F14 -> 1358000 | I14: =SUMIFS('ครุภัณฑ์ 69'!G:G,'ครุภัณฑ์ 69'!C:C,"ยานพาหนะและขนส่ง",'ครุภัณฑ์ 69'!E:E,B14) -> 0 | J14: =SUMIFS('ครุภัณฑ์ 69'!F:F,'ครุภัณฑ์ 69'!C:C,"ยานพาหนะและขนส่ง",'ครุภัณฑ์ 69'!E:E,B14) -> 0 | K14: =I14 -> 0 | L14: =SUMIFS('รวมครุภัณฑ์ 70'!L:L,'รวมครุภัณฑ์ 70'!C:C,"ครุภัณฑ์ยานพาหนะและขนส่ง",'รวมครุภัณฑ์ 70'!H:H,B14) -> 970900 | M14: =SUMIFS('รวมครุภัณฑ์ 70'!Q:Q,'รวมครุภัณฑ์ 70'!C:C,"ครุภัณฑ์ยานพาหนะและขนส่ง",'รวมครุภัณฑ์ 70'!H:H,B14) -> 1 | N14: =SUMIFS('รวมครุภัณฑ์ 70'!R:R,'รวมครุภัณฑ์ 70'!C:C,"ครุภัณฑ์ยานพาหนะและขนส่ง",'รวมครุภัณฑ์ 70'!H:H,B14) -> 0 | O14: =M14+N14 -> 1 | P14: =L14 -> 970900
A15: ลำพูน | B15: พมจ.ลำพูน | C15: =SUMIFS('ครุภัณฑ์ 67'!G:G,'ครุภัณฑ์ 67'!C:C,"ยานพาหนะและขนส่ง",'ครุภัณฑ์ 67'!E:E,B15) -> 0 | D15: =SUMIFS('ครุภัณฑ์ 67'!F:F,'ครุภัณฑ์ 67'!C:C,"ยานพาหนะและขนส่ง",'ครุภัณฑ์ 67'!E:E,B15) -> 0 | E15: =C15:C26 -> 0 | F15: =SUMIFS('ครุภัณฑ์ 68'!G:G,'ครุภัณฑ์ 68'!C:C,"ยานพาหนะและขนส่ง",'ครุภัณฑ์ 68'!E:E,B15) -> 0 | G15: =SUMIFS('ครุภัณฑ์ 68'!F:F,'ครุภัณฑ์ 68'!C:C,"ยานพาหนะและขนส่ง",'ครุภัณฑ์ 68'!E:E,B15) -> 0 | H15: =F15 -> 0 | I15: =SUMIFS('ครุภัณฑ์ 69'!G:G,'ครุภัณฑ์ 69'!C:C,"ยานพาหนะและขนส่ง",'ครุภัณฑ์ 69'!E:E,B15) -> 0 | J15: =SUMIFS('ครุภัณฑ์ 69'!F:F,'ครุภัณฑ์ 69'!C:C,"ยานพาหนะและขนส่ง",'ครุภัณฑ์ 69'!E:E,B15) -> 0 | K15: =I15 -> 0 | L15: =SUMIFS('รวมครุภัณฑ์ 70'!L:L,'รวมครุภัณฑ์ 70'!C:C,"ครุภัณฑ์ยานพาหนะและขนส่ง",'รวมครุภัณฑ์ 70'!H:H,B15) -> 2705900 | M15: =SUMIFS('รวมครุภัณฑ์ 70'!Q:Q,'รวมครุภัณฑ์ 70'!C:C,"ครุภัณฑ์ยานพาหนะและขนส่ง",'รวมครุภัณฑ์ 70'!H:H,B15) -> 2 | N15: =SUMIFS('รวมครุภัณฑ์ 70'!R:R,'รวมครุภัณฑ์ 70'!C:C,"ครุภัณฑ์ยานพาหนะและขนส่ง",'รวมครุภัณฑ์ 70'!H:H,B15) -> 0 | O15: =M15+N15 -> 2 | P15: =L15 -> 2705900
A16: อุตรดิตถ์ | B16: สสว.8 | C16: =SUMIFS('ครุภัณฑ์ 67'!G:G,'ครุภัณฑ์ 67'!C:C,"ยานพาหนะและขนส่ง",'ครุภัณฑ์ 67'!E:E,B16) -> 885900 | D16: =SUMIFS('ครุภัณฑ์ 67'!F:F,'ครุภัณฑ์ 67'!C:C,"ยานพาหนะและขนส่ง",'ครุภัณฑ์ 67'!E:E,B16) -> 1 | E16: =C16:C27 -> 885900 | F16: =SUMIFS('ครุภัณฑ์ 68'!G:G,'ครุภัณฑ์ 68'!C:C,"ยานพาหนะและขนส่ง",'ครุภัณฑ์ 68'!E:E,B16) -> 0 | G16: =SUMIFS('ครุภัณฑ์ 68'!F:F,'ครุภัณฑ์ 68'!C:C,"ยานพาหนะและขนส่ง",'ครุภัณฑ์ 68'!E:E,B16) -> 0 | H16: =F16 -> 0 | I16: =SUMIFS('ครุภัณฑ์ 69'!G:G,'ครุภัณฑ์ 69'!C:C,"ยานพาหนะและขนส่ง",'ครุภัณฑ์ 69'!E:E,B16) -> 1207900 | J16: =SUMIFS('ครุภัณฑ์ 69'!F:F,'ครุภัณฑ์ 69'!C:C,"ยานพาหนะและขนส่ง",'ครุภัณฑ์ 69'!E:E,B16) -> 1 | K16: =I16 -> 1207900 | L16: =SUMIFS('รวมครุภัณฑ์ 70'!L:L,'รวมครุภัณฑ์ 70'!C:C,"ครุภัณฑ์ยานพาหนะและขนส่ง",'รวมครุภัณฑ์ 70'!H:H,B16) -> 0 | M16: =SUMIFS('รวมครุภัณฑ์ 70'!Q:Q,'รวมครุภัณฑ์ 70'!C:C,"ครุภัณฑ์ยานพาหนะและขนส่ง",'รวมครุภัณฑ์ 70'!H:H,B16) -> 0 | N16: =SUMIFS('รวมครุภัณฑ์ 70'!R:R,'รวมครุภัณฑ์ 70'!C:C,"ครุภัณฑ์ยานพาหนะและขนส่ง",'รวมครุภัณฑ์ 70'!H:H,B16) -> 0 | O16: =M16+N16 -> 0 | P16: =L16 -> 0
A17: อุตรดิตถ์ | B17: พมจ.อุตรดิตถ์ | C17: =SUMIFS('ครุภัณฑ์ 67'!G:G,'ครุภัณฑ์ 67'!C:C,"ยานพาหนะและขนส่ง",'ครุภัณฑ์ 67'!E:E,B17) -> 0 | D17: =SUMIFS('ครุภัณฑ์ 67'!F:F,'ครุภัณฑ์ 67'!C:C,"ยานพาหนะและขนส่ง",'ครุภัณฑ์ 67'!E:E,B17) -> 0 | E17: =C17:C28 -> 0 | F17: =SUMIFS('ครุภัณฑ์ 68'!G:G,'ครุภัณฑ์ 68'!C:C,"ยานพาหนะและขนส่ง",'ครุภัณฑ์ 68'!E:E,B17) -> 1090900 | G17: =SUMIFS('ครุภัณฑ์ 68'!F:F,'ครุภัณฑ์ 68'!C:C,"ยานพาหนะและขนส่ง",'ครุภัณฑ์ 68'!E:E,B17) -> 1 | H17: =F17 -> 1090900 | I17: =SUMIFS('ครุภัณฑ์ 69'!G:G,'ครุภัณฑ์ 69'!C:C,"ยานพาหนะและขนส่ง",'ครุภัณฑ์ 69'!E:E,B17) -> 0 | J17: =SUMIFS('ครุภัณฑ์ 69'!F:F,'ครุภัณฑ์ 69'!C:C,"ยานพาหนะและขนส่ง",'ครุภัณฑ์ 69'!E:E,B17) -> 0 | K17: =I17 -> 0 | L17: =SUMIFS('รวมครุภัณฑ์ 70'!L:L,'รวมครุภัณฑ์ 70'!C:C,"ครุภัณฑ์ยานพาหนะและขนส่ง",'รวมครุภัณฑ์ 70'!H:H,B17) -> 2705900 | M17: =SUMIFS('รวมครุภัณฑ์ 70'!Q:Q,'รวมครุภัณฑ์ 70'!C:C,"ครุภัณฑ์ยานพาหนะและขนส่ง",'รวมครุภัณฑ์ 70'!H:H,B17) -> 2 | N17: =SUMIFS('รวมครุภัณฑ์ 70'!R:R,'รวมครุภัณฑ์ 70'!C:C,"ครุภัณฑ์ยานพาหนะและขนส่ง",'รวมครุภัณฑ์ 70'!H:H,B17) -> 0 | O17: =M17+N17 -> 2 | P17: =L17 -> 2705900
A18: ภาคตะวันออกเฉียงเหนือ
A19: กาฬสินธุ์ | B19: พมจ.กาฬสินธุ์ | C19: =SUMIFS('ครุภัณฑ์ 67'!G:G,'ครุภัณฑ์ 67'!C:C,"ยานพาหนะและขนส่ง",'ครุภัณฑ์ 67'!E:E,B19) -> 1976800 | D19: =SUMIFS('ครุภัณฑ์ 67'!F:F,'ครุภัณฑ์ 67'!C:C,"ยานพาหนะและขนส่ง",'ครุภัณฑ์ 67'!E:E,B19) -> 2 | E19: =C19:C30 -> 1976800 | F19: =SUMIFS('ครุภัณฑ์ 68'!G:G,'ครุภัณฑ์ 68'!C:C,"ยานพาหนะและขนส่ง",'ครุภัณฑ์ 68'!E:E,B19) -> 0 | G19: =SUMIFS('ครุภัณฑ์ 68'!F:F,'ครุภัณฑ์ 68'!C:C,"ยานพาหนะและขนส่ง",'ครุภัณฑ์ 68'!E:E,B19) -> 0 | H19: =F19 -> 0 | I19: =SUMIFS('ครุภัณฑ์ 69'!G:G,'ครุภัณฑ์ 69'!C:C,"ยานพาหนะและขนส่ง",'ครุภัณฑ์ 69'!E:E,B19) -> 970900 | J19: =SUMIFS('ครุภัณฑ์ 69'!F:F,'ครุภัณฑ์ 69'!C:C,"ยานพาหนะและขนส่ง",'ครุภัณฑ์ 69'!E:E,B19) -> 1 | K19: =I19 -> 970900 | L19: =SUMIFS('รวมครุภัณฑ์ 70'!L:L,'รวมครุภัณฑ์ 70'!C:C,"ครุภัณฑ์ยานพาหนะและขนส่ง",'รวมครุภัณฑ์ 70'!H:H,B19) -> 1498000 | M19: =SUMIFS('รวมครุภัณฑ์ 70'!Q:Q,'รวมครุภัณฑ์ 70'!C:C,"ครุภัณฑ์ยานพาหนะและขนส่ง",'รวมครุภัณฑ์ 70'!H:H,B19) -> 1 | N19: =SUMIFS('รวมครุภัณฑ์ 70'!R:R,'รวมครุภัณฑ์ 70'!C:C,"ครุภัณฑ์ยานพาหนะและขนส่ง",'รวมครุภัณฑ์ 70'!H:H,B19) -> 0 | O19: =M19+N19 -> 1 | P19: =L19 -> 1498000 | Q19: =SUM(L19:L42) -> 16485500
A20: กาฬสินธุ์ | B20: สสว.6 | C20: =SUMIFS('ครุภัณฑ์ 67'!G:G,'ครุภัณฑ์ 67'!C:C,"ยานพาหนะและขนส่ง",'ครุภัณฑ์ 67'!E:E,B20) -> 0 | D20: =SUMIFS('ครุภัณฑ์ 67'!F:F,'ครุภัณฑ์ 67'!C:C,"ยานพาหนะและขนส่ง",'ครุภัณฑ์ 67'!E:E,B20) -> 0 | E20: =C20:C31 -> 0 | F20: =SUMIFS('ครุภัณฑ์ 68'!G:G,'ครุภัณฑ์ 68'!C:C,"ยานพาหนะและขนส่ง",'ครุภัณฑ์ 68'!E:E,B20) -> 0 | G20: =SUMIFS('ครุภัณฑ์ 68'!F:F,'ครุภัณฑ์ 68'!C:C,"ยานพาหนะและขนส่ง",'ครุภัณฑ์ 68'!E:E,B20) -> 0 | H20: =F20 -> 0 | I20: =SUMIFS('ครุภัณฑ์ 69'!G:G,'ครุภัณฑ์ 69'!C:C,"ยานพาหนะและขนส่ง",'ครุภัณฑ์ 69'!E:E,B20) -> 1369000 | J20: =SUMIFS('ครุภัณฑ์ 69'!F:F,'ครุภัณฑ์ 69'!C:C,"ยานพาหนะและขนส่ง",'ครุภัณฑ์ 69'!E:E,B20) -> 1 | K20: =I20 -> 1369000 | L20: =SUMIFS('รวมครุภัณฑ์ 70'!L:L,'รวมครุภัณฑ์ 70'!C:C,"ครุภัณฑ์ยานพาหนะและขนส่ง",'รวมครุภัณฑ์ 70'!H:H,B20) -> 0 | M20: =SUMIFS('รวมครุภัณฑ์ 70'!Q:Q,'รวมครุภัณฑ์ 70'!C:C,"ครุภัณฑ์ยานพาหนะและขนส่ง",'รวมครุภัณฑ์ 70'!H:H,B20) -> 0 | N20: =SUMIFS('รวมครุภัณฑ์ 70'!R:R,'รวมครุภัณฑ์ 70'!C:C,"ครุภัณฑ์ยานพาหนะและขนส่ง",'รวมครุภัณฑ์ 70'!H:H,B20) -> 0 | O20: =M20+N20 -> 0 | P20: =L20 -> 0 | Q20: =SUM(#REF!) -> #REF!
A21: ขอนแก่น | B21: พมจ.ขอนแก่น | C21: =SUMIFS('ครุภัณฑ์ 67'!G:G,'ครุภัณฑ์ 67'!C:C,"ยานพาหนะและขนส่ง",'ครุภัณฑ์ 67'!E:E,B21) -> 0 | D21: =SUMIFS('ครุภัณฑ์ 67'!F:F,'ครุภัณฑ์ 67'!C:C,"ยานพาหนะและขนส่ง",'ครุภัณฑ์ 67'!E:E,B21) -> 0 | E21: =C21 -> 0 | F21: =SUMIFS('ครุภัณฑ์ 68'!G:G,'ครุภัณฑ์ 68'!C:C,"ยานพาหนะและขนส่ง",'ครุภัณฑ์ 68'!E:E,B21) -> 0 | G21: =SUMIFS('ครุภัณฑ์ 68'!F:F,'ครุภัณฑ์ 68'!C:C,"ยานพาหนะและขนส่ง",'ครุภัณฑ์ 68'!E:E,B21) -> 0 | H21: =F21 -> 0 | I21: =SUMIFS('ครุภัณฑ์ 69'!G:G,'ครุภัณฑ์ 69'!C:C,"ยานพาหนะและขนส่ง",'ครุภัณฑ์ 69'!E:E,B21) -> 0 | J21: =SUMIFS('ครุภัณฑ์ 69'!F:F,'ครุภัณฑ์ 69'!C:C,"ยานพาหนะและขนส่ง",'ครุภัณฑ์ 69'!E:E,B21) -> 0 | K21: =I21 -> 0 | L21: =SUMIFS('รวมครุภัณฑ์ 70'!L:L,'รวมครุภัณฑ์ 70'!C:C,"ครุภัณฑ์ยานพาหนะและขนส่ง",'รวมครุภัณฑ์ 70'!H:H,B21) -> 0 | M21: =SUMIFS('รวมครุภัณฑ์ 70'!Q:Q,'รวมครุภัณฑ์ 70'!C:C,"ครุภัณฑ์ยานพาหนะและขนส่ง",'รวมครุภัณฑ์ 70'!H:H,B21) -> 0 | N21: =SUMIFS('รวมครุภัณฑ์ 70'!R:R,'รวมครุภัณฑ์ 70'!C:C,"ครุภัณฑ์ยานพาหนะและขนส่ง",'รวมครุภัณฑ์ 70'!H:H,B21) -> 0 | O21: =M21+N21 -> 0 | P21: =L21 -> 0 | Q21: =SUM(P19:P42) -> 16485500
A22: ขอนแก่น | B22: สสว.5 | C22: =SUMIFS('ครุภัณฑ์ 67'!G:G,'ครุภัณฑ์ 67'!C:C,"ยานพาหนะและขนส่ง",'ครุภัณฑ์ 67'!E:E,B22) -> 1358000 | D22: =SUMIFS('ครุภัณฑ์ 67'!F:F,'ครุภัณฑ์ 67'!C:C,"ยานพาหนะและขนส่ง",'ครุภัณฑ์ 67'!E:E,B22) -> 1 | E22: =C22 -> 1358000 | F22: =SUMIFS('ครุภัณฑ์ 68'!G:G,'ครุภัณฑ์ 68'!C:C,"ยานพาหนะและขนส่ง",'ครุภัณฑ์ 68'!E:E,B22) -> 0 | G22: =SUMIFS('ครุภัณฑ์ 68'!F:F,'ครุภัณฑ์ 68'!C:C,"ยานพาหนะและขนส่ง",'ครุภัณฑ์ 68'!E:E,B22) -> 0 | H22: =F22 -> 0 | I22: =SUMIFS('ครุภัณฑ์ 69'!G:G,'ครุภัณฑ์ 69'!C:C,"ยานพาหนะและขนส่ง",'ครุภัณฑ์ 69'!E:E,B22) -> 0 | J22: =SUMIFS('ครุภัณฑ์ 69'!F:F,'ครุภัณฑ์ 69'!C:C,"ยานพาหนะและขนส่ง",'ครุภัณฑ์ 69'!E:E,B22) -> 0 | K22: =I22 -> 0 | L22: =SUMIFS('รวมครุภัณฑ์ 70'!L:L,'รวมครุภัณฑ์ 70'!C:C,"ครุภัณฑ์ยานพาหนะและขนส่ง",'รวมครุภัณฑ์ 70'!H:H,B22) -> 0 | M22: =SUMIFS('รวมครุภัณฑ์ 70'!Q:Q,'รวมครุภัณฑ์ 70'!C:C,"ครุภัณฑ์ยานพาหนะและขนส่ง",'รวมครุภัณฑ์ 70'!H:H,B22) -> 0 | N22: =SUMIFS('รวมครุภัณฑ์ 70'!R:R,'รวมครุภัณฑ์ 70'!C:C,"ครุภัณฑ์ยานพาหนะและขนส่ง",'รวมครุภัณฑ์ 70'!H:H,B22) -> 0 | O22: =M22+N22 -> 0 | P22: =L22 -> 0
A23: ชัยภูมิ | B23: พมจ.ชัยภูมิ | C23: =SUMIFS('ครุภัณฑ์ 67'!G:G,'ครุภัณฑ์ 67'!C:C,"ยานพาหนะและขนส่ง",'ครุภัณฑ์ 67'!E:E,B23) -> 1090900 | D23: =SUMIFS('ครุภัณฑ์ 67'!F:F,'ครุภัณฑ์ 67'!C:C,"ยานพาหนะและขนส่ง",'ครุภัณฑ์ 67'!E:E,B23) -> 1 | E23: =C23 -> 1090900 | F23: =SUMIFS('ครุภัณฑ์ 68'!G:G,'ครุภัณฑ์ 68'!C:C,"ยานพาหนะและขนส่ง",'ครุภัณฑ์ 68'!E:E,B23) -> 0 | G23: =SUMIFS('ครุภัณฑ์ 68'!F:F,'ครุภัณฑ์ 68'!C:C,"ยานพาหนะและขนส่ง",'ครุภัณฑ์ 68'!E:E,B23) -> 0 | H23: =F23 -> 0 | I23: =SUMIFS('ครุภัณฑ์ 69'!G:G,'ครุภัณฑ์ 69'!C:C,"ยานพาหนะและขนส่ง",'ครุภัณฑ์ 69'!E:E,B23) -> 0 | J23: =SUMIFS('ครุภัณฑ์ 69'!F:F,'ครุภัณฑ์ 69'!C:C,"ยานพาหนะและขนส่ง",'ครุภัณฑ์ 69'!E:E,B23) -> 0 | K23: =I23 -> 0 | L23: =SUMIFS('รวมครุภัณฑ์ 70'!L:L,'รวมครุภัณฑ์ 70'!C:C,"ครุภัณฑ์ยานพาหนะและขนส่ง",'รวมครุภัณฑ์ 70'!H:H,B23) -> 2415800 | M23: =SUMIFS('รวมครุภัณฑ์ 70'!Q:Q,'รวมครุภัณฑ์ 70'!C:C,"ครุภัณฑ์ยานพาหนะและขนส่ง",'รวมครุภัณฑ์ 70'!H:H,B23) -> 2 | N23: =SUMIFS('รวมครุภัณฑ์ 70'!R:R,'รวมครุภัณฑ์ 70'!C:C,"ครุภัณฑ์ยานพาหนะและขนส่ง",'รวมครุภัณฑ์ 70'!H:H,B23) -> 0 | O23: =M23+N23 -> 2 | P23: =L23 -> 2415800
A24: นครพนม | B24: พมจ.นครพนม | C24: =SUMIFS('ครุภัณฑ์ 67'!G:G,'ครุภัณฑ์ 67'!C:C,"ยานพาหนะและขนส่ง",'ครุภัณฑ์ 67'!E:E,B24) -> 1358000 | D24: =SUMIFS('ครุภัณฑ์ 67'!F:F,'ครุภัณฑ์ 67'!C:C,"ยานพาหนะและขนส่ง",'ครุภัณฑ์ 67'!E:E,B24) -> 1 | E24: =C24 -> 1358000 | F24: =SUMIFS('ครุภัณฑ์ 68'!G:G,'ครุภัณฑ์ 68'!C:C,"ยานพาหนะและขนส่ง",'ครุภัณฑ์ 68'!E:E,B24) -> 0 | G24: =SUMIFS('ครุภัณฑ์ 68'!F:F,'ครุภัณฑ์ 68'!C:C,"ยานพาหนะและขนส่ง",'ครุภัณฑ์ 68'!E:E,B24) -> 0 | H24: =F24 -> 0 | I24: =SUMIFS('ครุภัณฑ์ 69'!G:G,'ครุภัณฑ์ 69'!C:C,"ยานพาหนะและขนส่ง",'ครุภัณฑ์ 69'!E:E,B24) -> 0 | J24: =SUMIFS('ครุภัณฑ์ 69'!F:F,'ครุภัณฑ์ 69'!C:C,"ยานพาหนะและขนส่ง",'ครุภัณฑ์ 69'!E:E,B24) -> 0 | K24: =I24 -> 0 | L24: =SUMIFS('รวมครุภัณฑ์ 70'!L:L,'รวมครุภัณฑ์ 70'!C:C,"ครุภัณฑ์ยานพาหนะและขนส่ง",'รวมครุภัณฑ์ 70'!H:H,B24) -> 0 | M24: =SUMIFS('รวมครุภัณฑ์ 70'!Q:Q,'รวมครุภัณฑ์ 70'!C:C,"ครุภัณฑ์ยานพาหนะและขนส่ง",'รวมครุภัณฑ์ 70'!H:H,B24) -> 0 | N24: =SUMIFS('รวมครุภัณฑ์ 70'!R:R,'รวมครุภัณฑ์ 70'!C:C,"ครุภัณฑ์ยานพาหนะและขนส่ง",'รวมครุภัณฑ์ 70'!H:H,B24) -> 0 | O24: =M24+N24 -> 0 | P24: =L24 -> 0
A25: นครราชสีมา | B25: พมจ.นครราชสีมา | C25: =SUMIFS('ครุภัณฑ์ 67'!G:G,'ครุภัณฑ์ 67'!C:C,"ยานพาหนะและขนส่ง",'ครุภัณฑ์ 67'!E:E,B25) -> 1090900 | D25: =SUMIFS('ครุภัณฑ์ 67'!F:F,'ครุภัณฑ์ 67'!C:C,"ยานพาหนะและขนส่ง",'ครุภัณฑ์ 67'!E:E,B25) -> 1 | E25: =C25 -> 1090900 | F25: =SUMIFS('ครุภัณฑ์ 68'!G:G,'ครุภัณฑ์ 68'!C:C,"ยานพาหนะและขนส่ง",'ครุภัณฑ์ 68'!E:E,B25) -> 0 | G25: =SUMIFS('ครุภัณฑ์ 68'!F:F,'ครุภัณฑ์ 68'!C:C,"ยานพาหนะและขนส่ง",'ครุภัณฑ์ 68'!E:E,B25) -> 0 | H25: =F25 -> 0 | I25: =SUMIFS('ครุภัณฑ์ 69'!G:G,'ครุภัณฑ์ 69'!C:C,"ยานพาหนะและขนส่ง",'ครุภัณฑ์ 69'!E:E,B25) -> 0 | J25: =SUMIFS('ครุภัณฑ์ 69'!F:F,'ครุภัณฑ์ 69'!C:C,"ยานพาหนะและขนส่ง",'ครุภัณฑ์ 69'!E:E,B25) -> 0 | K25: =I25 -> 0 | L25: =SUMIFS('รวมครุภัณฑ์ 70'!L:L,'รวมครุภัณฑ์ 70'!C:C,"ครุภัณฑ์ยานพาหนะและขนส่ง",'รวมครุภัณฑ์ 70'!H:H,B25) -> 2975000 | M25: =SUMIFS('รวมครุภัณฑ์ 70'!Q:Q,'รวมครุภัณฑ์ 70'!C:C,"ครุภัณฑ์ยานพาหนะและขนส่ง",'รวมครุภัณฑ์ 70'!H:H,B25) -> 1 | N25: =SUMIFS('รวมครุภัณฑ์ 70'!R:R,'รวมครุภัณฑ์ 70'!C:C,"ครุภัณฑ์ยานพาหนะและขนส่ง",'รวมครุภัณฑ์ 70'!H:H,B25) -> 1 | O25: =M25+N25 -> 2 | P25: =L25 -> 2975000
A26: นครราชสีมา | B26: สคม.บ้านนารีสวัสดิ์ | C26: =SUMIFS('ครุภัณฑ์ 67'!G:G,'ครุภัณฑ์ 67'!C:C,"ยานพาหนะและขนส่ง",'ครุภัณฑ์ 67'!E:E,B26) -> 0 | D26: =SUMIFS('ครุภัณฑ์ 67'!F:F,'ครุภัณฑ์ 67'!C:C,"ยานพาหนะและขนส่ง",'ครุภัณฑ์ 67'!E:E,B26) -> 0 | E26: =C26 -> 0 | F26: =SUMIFS('ครุภัณฑ์ 68'!G:G,'ครุภัณฑ์ 68'!C:C,"ยานพาหนะและขนส่ง",'ครุภัณฑ์ 68'!E:E,B26) -> 0 | G26: =SUMIFS('ครุภัณฑ์ 68'!F:F,'ครุภัณฑ์ 68'!C:C,"ยานพาหนะและขนส่ง",'ครุภัณฑ์ 68'!E:E,B26) -> 0 | H26: =F26 -> 0 | I26: =SUMIFS('ครุภัณฑ์ 69'!G:G,'ครุภัณฑ์ 69'!C:C,"ยานพาหนะและขนส่ง",'ครุภัณฑ์ 69'!E:E,B26) -> 0 | J26: =SUMIFS('ครุภัณฑ์ 69'!F:F,'ครุภัณฑ์ 69'!C:C,"ยานพาหนะและขนส่ง",'ครุภัณฑ์ 69'!E:E,B26) -> 0 | K26: =I26 -> 0 | L26: =SUMIFS('รวมครุภัณฑ์ 70'!L:L,'รวมครุภัณฑ์ 70'!C:C,"ครุภัณฑ์ยานพาหนะและขนส่ง",'รวมครุภัณฑ์ 70'!H:H,B26) -> 0 | M26: =SUMIFS('รวมครุภัณฑ์ 70'!Q:Q,'รวมครุภัณฑ์ 70'!C:C,"ครุภัณฑ์ยานพาหนะและขนส่ง",'รวมครุภัณฑ์ 70'!H:H,B26) -> 0 | N26: =SUMIFS('รวมครุภัณฑ์ 70'!R:R,'รวมครุภัณฑ์ 70'!C:C,"ครุภัณฑ์ยานพาหนะและขนส่ง",'รวมครุภัณฑ์ 70'!H:H,B26) -> 0 | O26: =M26+N26 -> 0 | P26: =L26 -> 0
A27: นครราชสีมา | B27: สสว.4 | C27: =SUMIFS('ครุภัณฑ์ 67'!G:G,'ครุภัณฑ์ 67'!C:C,"ยานพาหนะและขนส่ง",'ครุภัณฑ์ 67'!E:E,B27) -> 0 | D27: =SUMIFS('ครุภัณฑ์ 67'!F:F,'ครุภัณฑ์ 67'!C:C,"ยานพาหนะและขนส่ง",'ครุภัณฑ์ 67'!E:E,B27) -> 0 | E27: =C27 -> 0 | F27: =SUMIFS('ครุภัณฑ์ 68'!G:G,'ครุภัณฑ์ 68'!C:C,"ยานพาหนะและขนส่ง",'ครุภัณฑ์ 68'!E:E,B27) -> 0 | G27: =SUMIFS('ครุภัณฑ์ 68'!F:F,'ครุภัณฑ์ 68'!C:C,"ยานพาหนะและขนส่ง",'ครุภัณฑ์ 68'!E:E,B27) -> 0 | H27: =F27 -> 0 | I27: =SUMIFS('ครุภัณฑ์ 69'!G:G,'ครุภัณฑ์ 69'!C:C,"ยานพาหนะและขนส่ง",'ครุภัณฑ์ 69'!E:E,B27) -> 1941800 | J27: =SUMIFS('ครุภัณฑ์ 69'!F:F,'ครุภัณฑ์ 69'!C:C,"ยานพาหนะและขนส่ง",'ครุภัณฑ์ 69'!E:E,B27) -> 2 | K27: =I27 -> 1941800 | L27: =SUMIFS('รวมครุภัณฑ์ 70'!L:L,'รวมครุภัณฑ์ 70'!C:C,"ครุภัณฑ์ยานพาหนะและขนส่ง",'รวมครุภัณฑ์ 70'!H:H,B27) -> 0 | M27: =SUMIFS('รวมครุภัณฑ์ 70'!Q:Q,'รวมครุภัณฑ์ 70'!C:C,"ครุภัณฑ์ยานพาหนะและขนส่ง",'รวมครุภัณฑ์ 70'!H:H,B27) -> 0 | N27: =SUMIFS('รวมครุภัณฑ์ 70'!R:R,'รวมครุภัณฑ์ 70'!C:C,"ครุภัณฑ์ยานพาหนะและขนส่ง",'รวมครุภัณฑ์ 70'!H:H,B27) -> 0 | O27: =M27+N27 -> 0 | P27: =L27 -> 0
A28: บึงกาฬ | B28: พมจ.บึงกาฬ | C28: =SUMIFS('ครุภัณฑ์ 67'!G:G,'ครุภัณฑ์ 67'!C:C,"ยานพาหนะและขนส่ง",'ครุภัณฑ์ 67'!E:E,B28) -> 0 | D28: =SUMIFS('ครุภัณฑ์ 67'!F:F,'ครุภัณฑ์ 67'!C:C,"ยานพาหนะและขนส่ง",'ครุภัณฑ์ 67'!E:E,B28) -> 0 | E28: =C28 -> 0 | F28: =SUMIFS('ครุภัณฑ์ 68'!G:G,'ครุภัณฑ์ 68'!C:C,"ยานพาหนะและขนส่ง",'ครุภัณฑ์ 68'!E:E,B28) -> 0 | G28: =SUMIFS('ครุภัณฑ์ 68'!F:F,'ครุภัณฑ์ 68'!C:C,"ยานพาหนะและขนส่ง",'ครุภัณฑ์ 68'!E:E,B28) -> 0 | H28: =F28 -> 0 | I28: =SUMIFS('ครุภัณฑ์ 69'!G:G,'ครุภัณฑ์ 69'!C:C,"ยานพาหนะและขนส่ง",'ครุภัณฑ์ 69'!E:E,B28) -> 0 | J28: =SUMIFS('ครุภัณฑ์ 69'!F:F,'ครุภัณฑ์ 69'!C:C,"ยานพาหนะและขนส่ง",'ครุภัณฑ์ 69'!E:E,B28) -> 0 | K28: =I28 -> 0 | L28: =SUMIFS('รวมครุภัณฑ์ 70'!L:L,'รวมครุภัณฑ์ 70'!C:C,"ครุภัณฑ์ยานพาหนะและขนส่ง",'รวมครุภัณฑ์ 70'!H:H,B28) -> 1207900 | M28: =SUMIFS('รวมครุภัณฑ์ 70'!Q:Q,'รวมครุภัณฑ์ 70'!C:C,"ครุภัณฑ์ยานพาหนะและขนส่ง",'รวมครุภัณฑ์ 70'!H:H,B28) -> 1 | N28: =SUMIFS('รวมครุภัณฑ์ 70'!R:R,'รวมครุภัณฑ์ 70'!C:C,"ครุภัณฑ์ยานพาหนะและขนส่ง",'รวมครุภัณฑ์ 70'!H:H,B28) -> 0 | O28: =M28+N28 -> 1 | P28: =L28 -> 1207900
A29: บุรีรัมย์ | B29: พมจ.บุรีรัมย์ | C29: =SUMIFS('ครุภัณฑ์ 67'!G:G,'ครุภัณฑ์ 67'!C:C,"ยานพาหนะและขนส่ง",'ครุภัณฑ์ 67'!E:E,B29) -> 3539800 | D29: =SUMIFS('ครุภัณฑ์ 67'!F:F,'ครุภัณฑ์ 67'!C:C,"ยานพาหนะและขนส่ง",'ครุภัณฑ์ 67'!E:E,B29) -> 3 | E29: =C29 -> 3539800 | F29: =SUMIFS('ครุภัณฑ์ 68'!G:G,'ครุภัณฑ์ 68'!C:C,"ยานพาหนะและขนส่ง",'ครุภัณฑ์ 68'!E:E,B29) -> 0 | G29: =SUMIFS('ครุภัณฑ์ 68'!F:F,'ครุภัณฑ์ 68'!C:C,"ยานพาหนะและขนส่ง",'ครุภัณฑ์ 68'!E:E,B29) -> 0 | H29: =F29 -> 0 | I29: =SUMIFS('ครุภัณฑ์ 69'!G:G,'ครุภัณฑ์ 69'!C:C,"ยานพาหนะและขนส่ง",'ครุภัณฑ์ 69'!E:E,B29) -> 0 | J29: =SUMIFS('ครุภัณฑ์ 69'!F:F,'ครุภัณฑ์ 69'!C:C,"ยานพาหนะและขนส่ง",'ครุภัณฑ์ 69'!E:E,B29) -> 0 | K29: =I29 -> 0 | L29: =SUMIFS('รวมครุภัณฑ์ 70'!L:L,'รวมครุภัณฑ์ 70'!C:C,"ครุภัณฑ์ยานพาหนะและขนส่ง",'รวมครุภัณฑ์ 70'!H:H,B29) -> 0 | M29: =SUMIFS('รวมครุภัณฑ์ 70'!Q:Q,'รวมครุภัณฑ์ 70'!C:C,"ครุภัณฑ์ยานพาหนะและขนส่ง",'รวมครุภัณฑ์ 70'!H:H,B29) -> 0 | N29: =SUMIFS('รวมครุภัณฑ์ 70'!R:R,'รวมครุภัณฑ์ 70'!C:C,"ครุภัณฑ์ยานพาหนะและขนส่ง",'รวมครุภัณฑ์ 70'!H:H,B29) -> 0 | O29: =M29+N29 -> 0 | P29: =L29 -> 0
A30: มหาสารคาม | B30: พมจ.มหาสารคาม | C30: =SUMIFS('ครุภัณฑ์ 67'!G:G,'ครุภัณฑ์ 67'!C:C,"ยานพาหนะและขนส่ง",'ครุภัณฑ์ 67'!E:E,B30) -> 0 | D30: =SUMIFS('ครุภัณฑ์ 67'!F:F,'ครุภัณฑ์ 67'!C:C,"ยานพาหนะและขนส่ง",'ครุภัณฑ์ 67'!E:E,B30) -> 0 | E30: =C30 -> 0 | F30: =SUMIFS('ครุภัณฑ์ 68'!G:G,'ครุภัณฑ์ 68'!C:C,"ยานพาหนะและขนส่ง",'ครุภัณฑ์ 68'!E:E,B30) -> 0 | G30: =SUMIFS('ครุภัณฑ์ 68'!F:F,'ครุภัณฑ์ 68'!C:C,"ยานพาหนะและขนส่ง",'ครุภัณฑ์ 68'!E:E,B30) -> 0 | H30: =F30 -> 0 | I30: =SUMIFS('ครุภัณฑ์ 69'!G:G,'ครุภัณฑ์ 69'!C:C,"ยานพาหนะและขนส่ง",'ครุภัณฑ์ 69'!E:E,B30) -> 0 | J30: =SUMIFS('ครุภัณฑ์ 69'!F:F,'ครุภัณฑ์ 69'!C:C,"ยานพาหนะและขนส่ง",'ครุภัณฑ์ 69'!E:E,B30) -> 0 | K30: =I30 -> 0 | L30: =SUMIFS('รวมครุภัณฑ์ 70'!L:L,'รวมครุภัณฑ์ 70'!C:C,"ครุภัณฑ์ยานพาหนะและขนส่ง",'รวมครุภัณฑ์ 70'!H:H,B30) -> 0 | M30: =SUMIFS('รวมครุภัณฑ์ 70'!Q:Q,'รวมครุภัณฑ์ 70'!C:C,"ครุภัณฑ์ยานพาหนะและขนส่ง",'รวมครุภัณฑ์ 70'!H:H,B30) -> 0 | N30: =SUMIFS('รวมครุภัณฑ์ 70'!R:R,'รวมครุภัณฑ์ 70'!C:C,"ครุภัณฑ์ยานพาหนะและขนส่ง",'รวมครุภัณฑ์ 70'!H:H,B30) -> 0 | O30: =M30+N30 -> 0 | P30: =L30 -> 0
A31: มุกดาหาร | B31: พมจ.มุกดาหาร | C31: =SUMIFS('ครุภัณฑ์ 67'!G:G,'ครุภัณฑ์ 67'!C:C,"ยานพาหนะและขนส่ง",'ครุภัณฑ์ 67'!E:E,B31) -> 0 | D31: =SUMIFS('ครุภัณฑ์ 67'!F:F,'ครุภัณฑ์ 67'!C:C,"ยานพาหนะและขนส่ง",'ครุภัณฑ์ 67'!E:E,B31) -> 0 | E31: =C31 -> 0 | F31: =SUMIFS('ครุภัณฑ์ 68'!G:G,'ครุภัณฑ์ 68'!C:C,"ยานพาหนะและขนส่ง",'ครุภัณฑ์ 68'!E:E,B31) -> 0 | G31: =SUMIFS('ครุภัณฑ์ 68'!F:F,'ครุภัณฑ์ 68'!C:C,"ยานพาหนะและขนส่ง",'ครุภัณฑ์ 68'!E:E,B31) -> 0 | H31: =F31 -> 0 | I31: =SUMIFS('ครุภัณฑ์ 69'!G:G,'ครุภัณฑ์ 69'!C:C,"ยานพาหนะและขนส่ง",'ครุภัณฑ์ 69'!E:E,B31) -> 0 | J31: =SUMIFS('ครุภัณฑ์ 69'!F:F,'ครุภัณฑ์ 69'!C:C,"ยานพาหนะและขนส่ง",'ครุภัณฑ์ 69'!E:E,B31) -> 0 | K31: =I31 -> 0 | L31: =SUMIFS('รวมครุภัณฑ์ 70'!L:L,'รวมครุภัณฑ์ 70'!C:C,"ครุภัณฑ์ยานพาหนะและขนส่ง",'รวมครุภัณฑ์ 70'!H:H,B31) -> 0 | M31: =SUMIFS('รวมครุภัณฑ์ 70'!Q:Q,'รวมครุภัณฑ์ 70'!C:C,"ครุภัณฑ์ยานพาหนะและขนส่ง",'รวมครุภัณฑ์ 70'!H:H,B31) -> 0 | N31: =SUMIFS('รวมครุภัณฑ์ 70'!R:R,'รวมครุภัณฑ์ 70'!C:C,"ครุภัณฑ์ยานพาหนะและขนส่ง",'รวมครุภัณฑ์ 70'!H:H,B31) -> 0 | O31: =M31+N31 -> 0 | P31: =L31 -> 0
A32: ยโสธร | B32: พมจ.ยโสธร | C32: =SUMIFS('ครุภัณฑ์ 67'!G:G,'ครุภัณฑ์ 67'!C:C,"ยานพาหนะและขนส่ง",'ครุภัณฑ์ 67'!E:E,B32) -> 0 | D32: =SUMIFS('ครุภัณฑ์ 67'!F:F,'ครุภัณฑ์ 67'!C:C,"ยานพาหนะและขนส่ง",'ครุภัณฑ์ 67'!E:E,B32) -> 0 | E32: =C32 -> 0 | F32: =SUMIFS('ครุภัณฑ์ 68'!G:G,'ครุภัณฑ์ 68'!C:C,"ยานพาหนะและขนส่ง",'ครุภัณฑ์ 68'!E:E,B32) -> 0 | G32: =SUMIFS('ครุภัณฑ์ 68'!F:F,'ครุภัณฑ์ 68'!C:C,"ยานพาหนะและขนส่ง",'ครุภัณฑ์ 68'!E:E,B32) -> 0 | H32: =F32 -> 0 | I32: =SUMIFS('ครุภัณฑ์ 69'!G:G,'ครุภัณฑ์ 69'!C:C,"ยานพาหนะและขนส่ง",'ครุภัณฑ์ 69'!E:E,B32) -> 970900 | J32: =SUMIFS('ครุภัณฑ์ 69'!F:F,'ครุภัณฑ์ 69'!C:C,"ยานพาหนะและขนส่ง",'ครุภัณฑ์ 69'!E:E,B32) -> 1 | K32: =I32 -> 970900 | L32: =SUMIFS('รวมครุภัณฑ์ 70'!L:L,'รวมครุภัณฑ์ 70'!C:C,"ครุภัณฑ์ยานพาหนะและขนส่ง",'รวมครุภัณฑ์ 70'!H:H,B32) -> 52000 | M32: =SUMIFS('รวมครุภัณฑ์ 70'!Q:Q,'รวมครุภัณฑ์ 70'!C:C,"ครุภัณฑ์ยานพาหนะและขนส่ง",'รวมครุภัณฑ์ 70'!H:H,B32) -> 1 | N32: =SUMIFS('รวมครุภัณฑ์ 70'!R:R,'รวมครุภัณฑ์ 70'!C:C,"ครุภัณฑ์ยานพาหนะและขนส่ง",'รวมครุภัณฑ์ 70'!H:H,B32) -> 0 | O32: =M32+N32 -> 1 | P32: =L32 -> 52000
A33: ร้อยเอ็ด | B33: พมจ.ร้อยเอ็ด | C33: =SUMIFS('ครุภัณฑ์ 67'!G:G,'ครุภัณฑ์ 67'!C:C,"ยานพาหนะและขนส่ง",'ครุภัณฑ์ 67'!E:E,B33) -> 1090900 | D33: =SUMIFS('ครุภัณฑ์ 67'!F:F,'ครุภัณฑ์ 67'!C:C,"ยานพาหนะและขนส่ง",'ครุภัณฑ์ 67'!E:E,B33) -> 1 | E33: =C33 -> 1090900 | F33: =SUMIFS('ครุภัณฑ์ 68'!G:G,'ครุภัณฑ์ 68'!C:C,"ยานพาหนะและขนส่ง",'ครุภัณฑ์ 68'!E:E,B33) -> 1358000 | G33: =SUMIFS('ครุภัณฑ์ 68'!F:F,'ครุภัณฑ์ 68'!C:C,"ยานพาหนะและขนส่ง",'ครุภัณฑ์ 68'!E:E,B33) -> 1 | H33: =F33 -> 1358000 | I33: =SUMIFS('ครุภัณฑ์ 69'!G:G,'ครุภัณฑ์ 69'!C:C,"ยานพาหนะและขนส่ง",'ครุภัณฑ์ 69'!E:E,B33) -> 0 | J33: =SUMIFS('ครุภัณฑ์ 69'!F:F,'ครุภัณฑ์ 69'!C:C,"ยานพาหนะและขนส่ง",'ครุภัณฑ์ 69'!E:E,B33) -> 0 | K33: =I33 -> 0 | L33: =SUMIFS('รวมครุภัณฑ์ 70'!L:L,'รวมครุภัณฑ์ 70'!C:C,"ครุภัณฑ์ยานพาหนะและขนส่ง",'รวมครุภัณฑ์ 70'!H:H,B33) -> 0 | M33: =SUMIFS('รวมครุภัณฑ์ 70'!Q:Q,'รวมครุภัณฑ์ 70'!C:C,"ครุภัณฑ์ยานพาหนะและขนส่ง",'รวมครุภัณฑ์ 70'!H:H,B33) -> 0 | N33: =SUMIFS('รวมครุภัณฑ์ 70'!R:R,'รวมครุภัณฑ์ 70'!C:C,"ครุภัณฑ์ยานพาหนะและขนส่ง",'รวมครุภัณฑ์ 70'!H:H,B33) -> 0 | O33: =M33+N33 -> 0 | P33: =L33 -> 0
... A42: อุบลราชธานี | B42: พมจ.อุบลราชธานี | C42: =SUMIFS('ครุภัณฑ์ 67'!G:G,'ครุภัณฑ์ 67'!C:C,"ยานพาหนะและขนส่ง",'ครุภัณฑ์ 67'!E:E,B42) -> 0 | D42: =SUMIFS('ครุภัณฑ์ 67'!F:F,'ครุภัณฑ์ 67'!C:C,"ยานพาหนะและขนส่ง",'ครุภัณฑ์ 67'!E:E,B42) -> 0 | E42: =C42 -> 0 | F42: =SUMIFS('ครุภัณฑ์ 68'!G:G,'ครุภัณฑ์ 68'!C:C,"ยานพาหนะและขนส่ง",'ครุภัณฑ์ 68'!E:E,B42) -> 0 | G42: =SUMIFS('ครุภัณฑ์ 68'!F:F,'ครุภัณฑ์ 68'!C:C,"ยานพาหนะและขนส่ง",'ครุภัณฑ์ 68'!E:E,B42) -> 0 | H42: =F42 -> 0 | I42: =SUMIFS('ครุภัณฑ์ 69'!G:G,'ครุภัณฑ์ 69'!C:C,"ยานพาหนะและขนส่ง",'ครุภัณฑ์ 69'!E:E,B42) -> 0 | J42: =SUMIFS('ครุภัณฑ์ 69'!F:F,'ครุภัณฑ์ 69'!C:C,"ยานพาหนะและขนส่ง",'ครุภัณฑ์ 69'!E:E,B42) -> 0 | K42: =I42 -> 0 | L42: =SUMIFS('รวมครุภัณฑ์ 70'!L:L,'รวมครุภัณฑ์ 70'!C:C,"ครุภัณฑ์ยานพาหนะและขนส่ง",'รวมครุภัณฑ์ 70'!H:H,B42) -> 1498000 | M42: =SUMIFS('รวมครุภัณฑ์ 70'!Q:Q,'รวมครุภัณฑ์ 70'!C:C,"ครุภัณฑ์ยานพาหนะและขนส่ง",'รวมครุภัณฑ์ 70'!H:H,B42) -> 1 | N42: =SUMIFS('รวมครุภัณฑ์ 70'!R:R,'รวมครุภัณฑ์ 70'!C:C,"ครุภัณฑ์ยานพาหนะและขนส่ง",'รวมครุภัณฑ์ 70'!H:H,B42) -> 0 | O42: =M42+N42 -> 1 | P42: =L42 -> 1498000
A43: ภาคกลาง (รวมภาคตะวันออกและตะวันตก)
A44: กรุงเทพมหานคร | B44: กก. | C44: =SUMIFS('ครุภัณฑ์ 67'!G:G,'ครุภัณฑ์ 67'!C:C,"ยานพาหนะและขนส่ง",'ครุภัณฑ์ 67'!E:E,B44) -> 2749000 | D44: =SUMIFS('ครุภัณฑ์ 67'!F:F,'ครุภัณฑ์ 67'!C:C,"ยานพาหนะและขนส่ง",'ครุภัณฑ์ 67'!E:E,B44) -> 1 | E44: =C44 -> 2749000 | F44: =SUMIFS('ครุภัณฑ์ 68'!G:G,'ครุภัณฑ์ 68'!C:C,"ยานพาหนะและขนส่ง",'ครุภัณฑ์ 68'!E:E,B44) -> 0 | G44: =SUMIFS('ครุภัณฑ์ 68'!F:F,'ครุภัณฑ์ 68'!C:C,"ยานพาหนะและขนส่ง",'ครุภัณฑ์ 68'!E:E,B44) -> 0 | H44: =F44 -> 0 | I44: =SUMIFS('ครุภัณฑ์ 69'!G:G,'ครุภัณฑ์ 69'!C:C,"ยานพาหนะและขนส่ง",'ครุภัณฑ์ 69'!E:E,B44) -> 1836000 | J44: =SUMIFS('ครุภัณฑ์ 69'!F:F,'ครุภัณฑ์ 69'!C:C,"ยานพาหนะและขนส่ง",'ครุภัณฑ์ 69'!E:E,B44) -> 2 | K44: =I44 -> 1836000 | L44: =SUMIFS('รวมครุภัณฑ์ 70'!L:L,'รวมครุภัณฑ์ 70'!C:C,"ครุภัณฑ์ยานพาหนะและขนส่ง",'รวมครุภัณฑ์ 70'!H:H,B44) -> 9522000 | M44: =SUMIFS('รวมครุภัณฑ์ 70'!Q:Q,'รวมครุภัณฑ์ 70'!C:C,"ครุภัณฑ์ยานพาหนะและขนส่ง",'รวมครุภัณฑ์ 70'!H:H,B44) -> 6 | N44: =SUMIFS('รวมครุภัณฑ์ 70'!R:R,'รวมครุภัณฑ์ 70'!C:C,"ครุภัณฑ์ยานพาหนะและขนส่ง",'รวมครุภัณฑ์ 70'!H:H,B44) -> 0 | O44: =M44+N44 -> 6 | P44: =L44 -> 9522000 | Q44: =SUM(L44:L95) -> 54641100
A45: กรุงเทพมหานคร | B45: กคม. | C45: =SUMIFS('ครุภัณฑ์ 67'!G:G,'ครุภัณฑ์ 67'!C:C,"ยานพาหนะและขนส่ง",'ครุภัณฑ์ 67'!E:E,B45) -> 0 | D45: =SUMIFS('ครุภัณฑ์ 67'!F:F,'ครุภัณฑ์ 67'!C:C,"ยานพาหนะและขนส่ง",'ครุภัณฑ์ 67'!E:E,B45) -> 0 | E45: =C45 -> 0 | F45: =SUMIFS('ครุภัณฑ์ 68'!G:G,'ครุภัณฑ์ 68'!C:C,"ยานพาหนะและขนส่ง",'ครุภัณฑ์ 68'!E:E,B45) -> 0 | G45: =SUMIFS('ครุภัณฑ์ 68'!F:F,'ครุภัณฑ์ 68'!C:C,"ยานพาหนะและขนส่ง",'ครุภัณฑ์ 68'!E:E,B45) -> 0 | H45: =F45 -> 0 | I45: =SUMIFS('ครุภัณฑ์ 69'!G:G,'ครุภัณฑ์ 69'!C:C,"ยานพาหนะและขนส่ง",'ครุภัณฑ์ 69'!E:E,B45) -> 918000 | J45: =SUMIFS('ครุภัณฑ์ 69'!F:F,'ครุภัณฑ์ 69'!C:C,"ยานพาหนะและขนส่ง",'ครุภัณฑ์ 69'!E:E,B45) -> 1 | K45: =I45 -> 918000 | L45: =SUMIFS('รวมครุภัณฑ์ 70'!L:L,'รวมครุภัณฑ์ 70'!C:C,"ครุภัณฑ์ยานพาหนะและขนส่ง",'รวมครุภัณฑ์ 70'!H:H,B45) -> 5701900 | M45: =SUMIFS('รวมครุภัณฑ์ 70'!Q:Q,'รวมครุภัณฑ์ 70'!C:C,"ครุภัณฑ์ยานพาหนะและขนส่ง",'รวมครุภัณฑ์ 70'!H:H,B45) -> 5 | N45: =SUMIFS('รวมครุภัณฑ์ 70'!R:R,'รวมครุภัณฑ์ 70'!C:C,"ครุภัณฑ์ยานพาหนะและขนส่ง",'รวมครุภัณฑ์ 70'!H:H,B45) -> 0 | O45: =M45+N45 -> 5 | P45: =L45 -> 5701900 | Q45: =SUM(#REF!) -> #REF!
A46: กรุงเทพมหานคร | B46: กตร. | C46: =SUMIFS('ครุภัณฑ์ 67'!G:G,'ครุภัณฑ์ 67'!C:C,"ยานพาหนะและขนส่ง",'ครุภัณฑ์ 67'!E:E,B46) -> 21326000 | D46: =SUMIFS('ครุภัณฑ์ 67'!F:F,'ครุภัณฑ์ 67'!C:C,"ยานพาหนะและขนส่ง",'ครุภัณฑ์ 67'!E:E,B46) -> 13 | E46: =C46 -> 21326000 | F46: =SUMIFS('ครุภัณฑ์ 68'!G:G,'ครุภัณฑ์ 68'!C:C,"ยานพาหนะและขนส่ง",'ครุภัณฑ์ 68'!E:E,B46) -> 0 | G46: =SUMIFS('ครุภัณฑ์ 68'!F:F,'ครุภัณฑ์ 68'!C:C,"ยานพาหนะและขนส่ง",'ครุภัณฑ์ 68'!E:E,B46) -> 0 | H46: =F46 -> 0 | I46: =SUMIFS('ครุภัณฑ์ 69'!G:G,'ครุภัณฑ์ 69'!C:C,"ยานพาหนะและขนส่ง",'ครุภัณฑ์ 69'!E:E,B46) -> 0 | J46: =SUMIFS('ครุภัณฑ์ 69'!F:F,'ครุภัณฑ์ 69'!C:C,"ยานพาหนะและขนส่ง",'ครุภัณฑ์ 69'!E:E,B46) -> 0 | K46: =I46 -> 0 | L46: =SUMIFS('รวมครุภัณฑ์ 70'!L:L,'รวมครุภัณฑ์ 70'!C:C,"ครุภัณฑ์ยานพาหนะและขนส่ง",'รวมครุภัณฑ์ 70'!H:H,B46) -> 10913900 | M46: =SUMIFS('รวมครุภัณฑ์ 70'!Q:Q,'รวมครุภัณฑ์ 70'!C:C,"ครุภัณฑ์ยานพาหนะและขนส่ง",'รวมครุภัณฑ์ 70'!H:H,B46) -> 3 | N46: =SUMIFS('รวมครุภัณฑ์ 70'!R:R,'รวมครุภัณฑ์ 70'!C:C,"ครุภัณฑ์ยานพาหนะและขนส่ง",'รวมครุภัณฑ์ 70'!H:H,B46) -> 3 | O46: =M46+N46 -> 6 | P46: =L46 -> 10913900 | Q46: =Q44+Q45 -> #REF!
A47: กรุงเทพมหานคร | B47: กมพ. | C47: =SUMIFS('ครุภัณฑ์ 67'!G:G,'ครุภัณฑ์ 67'!C:C,"ยานพาหนะและขนส่ง",'ครุภัณฑ์ 67'!E:E,B47) -> 0 | D47: =SUMIFS('ครุภัณฑ์ 67'!F:F,'ครุภัณฑ์ 67'!C:C,"ยานพาหนะและขนส่ง",'ครุภัณฑ์ 67'!E:E,B47) -> 0 | E47: =C47 -> 0 | F47: =SUMIFS('ครุภัณฑ์ 68'!G:G,'ครุภัณฑ์ 68'!C:C,"ยานพาหนะและขนส่ง",'ครุภัณฑ์ 68'!E:E,B47) -> 1358000 | G47: =SUMIFS('ครุภัณฑ์ 68'!F:F,'ครุภัณฑ์ 68'!C:C,"ยานพาหนะและขนส่ง",'ครุภัณฑ์ 68'!E:E,B47) -> 1 | H47: =F47 -> 1358000 | I47: =SUMIFS('ครุภัณฑ์ 69'!G:G,'ครุภัณฑ์ 69'!C:C,"ยานพาหนะและขนส่ง",'ครุภัณฑ์ 69'!E:E,B47) -> 0 | J47: =SUMIFS('ครุภัณฑ์ 69'!F:F,'ครุภัณฑ์ 69'!C:C,"ยานพาหนะและขนส่ง",'ครุภัณฑ์ 69'!E:E,B47) -> 0 | K47: =I47 -> 0 | L47: =SUMIFS('รวมครุภัณฑ์ 70'!L:L,'รวมครุภัณฑ์ 70'!C:C,"ครุภัณฑ์ยานพาหนะและขนส่ง",'รวมครุภัณฑ์ 70'!H:H,B47) -> 0 | M47: =SUMIFS('รวมครุภัณฑ์ 70'!Q:Q,'รวมครุภัณฑ์ 70'!C:C,"ครุภัณฑ์ยานพาหนะและขนส่ง",'รวมครุภัณฑ์ 70'!H:H,B47) -> 0 | N47: =SUMIFS('รวมครุภัณฑ์ 70'!R:R,'รวมครุภัณฑ์ 70'!C:C,"ครุภัณฑ์ยานพาหนะและขนส่ง",'รวมครุภัณฑ์ 70'!H:H,B47) -> 0 | O47: =M47+N47 -> 0 | P47: =L47 -> 0
A48: กรุงเทพมหานคร | B48: กยผ. | C48: =SUMIFS('ครุภัณฑ์ 67'!G:G,'ครุภัณฑ์ 67'!C:C,"ยานพาหนะและขนส่ง",'ครุภัณฑ์ 67'!E:E,B48) -> 0 | D48: =SUMIFS('ครุภัณฑ์ 67'!F:F,'ครุภัณฑ์ 67'!C:C,"ยานพาหนะและขนส่ง",'ครุภัณฑ์ 67'!E:E,B48) -> 0 | E48: =C48 -> 0 | F48: =SUMIFS('ครุภัณฑ์ 68'!G:G,'ครุภัณฑ์ 68'!C:C,"ยานพาหนะและขนส่ง",'ครุภัณฑ์ 68'!E:E,B48) -> 0 | G48: =SUMIFS('ครุภัณฑ์ 68'!F:F,'ครุภัณฑ์ 68'!C:C,"ยานพาหนะและขนส่ง",'ครุภัณฑ์ 68'!E:E,B48) -> 0 | H48: =F48 -> 0 | I48: =SUMIFS('ครุภัณฑ์ 69'!G:G,'ครุภัณฑ์ 69'!C:C,"ยานพาหนะและขนส่ง",'ครุภัณฑ์ 69'!E:E,B48) -> 918000 | J48: =SUMIFS('ครุภัณฑ์ 69'!F:F,'ครุภัณฑ์ 69'!C:C,"ยานพาหนะและขนส่ง",'ครุภัณฑ์ 69'!E:E,B48) -> 1 | K48: =I48 -> 918000 | L48: =SUMIFS('รวมครุภัณฑ์ 70'!L:L,'รวมครุภัณฑ์ 70'!C:C,"ครุภัณฑ์ยานพาหนะและขนส่ง",'รวมครุภัณฑ์ 70'!H:H,B48) -> 0 | M48: =SUMIFS('รวมครุภัณฑ์ 70'!Q:Q,'รวมครุภัณฑ์ 70'!C:C,"ครุภัณฑ์ยานพาหนะและขนส่ง",'รวมครุภัณฑ์ 70'!H:H,B48) -> 0 | N48: =SUMIFS('รวมครุภัณฑ์ 70'!R:R,'รวมครุภัณฑ์ 70'!C:C,"ครุภัณฑ์ยานพาหนะและขนส่ง",'รวมครุภัณฑ์ 70'!H:H,B48) -> 0 | O48: =M48+N48 -> 0 | P48: =L48 -> 0
A49: กรุงเทพมหานคร | B49: กตภ. | C49: =SUMIFS('ครุภัณฑ์ 67'!G:G,'ครุภัณฑ์ 67'!C:C,"ยานพาหนะและขนส่ง",'ครุภัณฑ์ 67'!E:E,B49) -> 0 | D49: =SUMIFS('ครุภัณฑ์ 67'!F:F,'ครุภัณฑ์ 67'!C:C,"ยานพาหนะและขนส่ง",'ครุภัณฑ์ 67'!E:E,B49) -> 0 | E49: =C49 -> 0 | F49: =SUMIFS('ครุภัณฑ์ 68'!G:G,'ครุภัณฑ์ 68'!C:C,"ยานพาหนะและขนส่ง",'ครุภัณฑ์ 68'!E:E,B49) -> 0 | G49: =SUMIFS('ครุภัณฑ์ 68'!F:F,'ครุภัณฑ์ 68'!C:C,"ยานพาหนะและขนส่ง",'ครุภัณฑ์ 68'!E:E,B49) -> 0 | H49: =F49 -> 0 | I49: =SUMIFS('ครุภัณฑ์ 69'!G:G,'ครุภัณฑ์ 69'!C:C,"ยานพาหนะและขนส่ง",'ครุภัณฑ์ 69'!E:E,B49) -> 0 | J49: =SUMIFS('ครุภัณฑ์ 69'!F:F,'ครุภัณฑ์ 69'!C:C,"ยานพาหนะและขนส่ง",'ครุภัณฑ์ 69'!E:E,B49) -> 0 | K49: =I49 -> 0 | L49: =SUMIFS('รวมครุภัณฑ์ 70'!L:L,'รวมครุภัณฑ์ 70'!C:C,"ครุภัณฑ์ยานพาหนะและขนส่ง",'รวมครุภัณฑ์ 70'!H:H,B49) -> 1498000 | M49: =SUMIFS('รวมครุภัณฑ์ 70'!Q:Q,'รวมครุภัณฑ์ 70'!C:C,"ครุภัณฑ์ยานพาหนะและขนส่ง",'รวมครุภัณฑ์ 70'!H:H,B49) -> 1 | N49: =SUMIFS('รวมครุภัณฑ์ 70'!R:R,'รวมครุภัณฑ์ 70'!C:C,"ครุภัณฑ์ยานพาหนะและขนส่ง",'รวมครุภัณฑ์ 70'!H:H,B49) -> 0 | O49: =M49+N49 -> 1 | P49: =L49 -> 1498000
...

Sheet BudgetData
A1: BudgetID | B1: ปี | C1: ประเภทงบ | D1: หมวด | E1: รายการ | F1: หน่วยงาน | G1: จังหวัด | H1: ทดแทนจำนวน | I1: เพิ่มประสิทธิภาพจำนวน | J1: รวมคำขอทั้งสิ้น | K1: งบประมาณ | L1: ประเภทคำขอ
A2: B000001 | B2: 2567 | C2: ครุภัณฑ์ | D2: ยานพาหนะและขนส่ง | E2: รถโดยสาร ขนาด 12 ที่นั่ง (ดีเซล) ปริมาตรกระบอกสูบไม่ต่ำกว่า 2,400 ซีซี หรือกำลังเครื่องยนต์สูงสุดไม่ต่ำกว่า 90 กิโลวัตต์ สำนักงานส่งเสริมและสนับสนุนวิชาการ 9 ตำบลช้างเผือก อำเภอเมืองเชียงใหม่ จังหวัดเชียงใหม่ | F2: สสว.9 | G2: เชียงใหม่ | H2: 1 | I2: 0 | J2: =Table47[[#This Row],[ทดแทนจำนวน]]+Table47[[#This Row],[เพิ่มประสิทธิภาพจำนวน]] -> 1 | K2: 1358000
A3: B000002 | B3: 2567 | C3: ครุภัณฑ์ | D3: ยานพาหนะและขนส่ง | E3: รถบรรทุก (ดีเซล) ขนาด 1 ตัน ปริมาตรกระบอกสูบไม่ต่ำกว่า 2,400 ซีซี หรือกำลังเครื่องยนต์สูงสุดไม่ต่ำกว่า 110 กิโลวัตต์ ขับเคลื่อน 4 ล้อ แบบดับเบิ้ลแค็บ พร้อมหลังคาไฟเบอร์กลาสหรือเหล็ก สำนักงานส่งเสริมและสนับสนุนวิชาการ 9 ตำบลช้างเผือก อำเภอเมืองเชียงใหม่ จังหวัดเชียงใหม่ | F3: สสว.9 | G3: เชียงใหม่ | H3: 1 | I3: 0 | J3: =Table47[[#This Row],[ทดแทนจำนวน]]+Table47[[#This Row],[เพิ่มประสิทธิภาพจำนวน]] -> 1 | K3: 1090900
A4: B000003 | B4: 2567 | C4: ครุภัณฑ์ | D4: ยานพาหนะและขนส่ง | E4: รถโดยสาร ขนาด 12 ที่นั่ง (ดีเซล) ปริมาตรกระบอกสูบไม่ต่ำกว่า 2,400 ซีซี หรือกำลังเครื่องยนต์สูงสุดไม่ต่ำกว่า 90 กิโลวัตต์ สำนักงานพัฒนาสังคมและความมั่นคงของมนุษย์จังหวัดน่าน ตำบลไชยสถาน อำเภอเมืองน่าน จังหวัดน่าน | F4: พมจ.น่าน | G4: น่าน | H4: 1 | I4: 0 | J4: =Table47[[#This Row],[ทดแทนจำนวน]]+Table47[[#This Row],[เพิ่มประสิทธิภาพจำนวน]] -> 1 | K4: 1358000
A5: B000004 | B5: 2567 | C5: ครุภัณฑ์ | D5: สำนักงาน | E5: เครื่องถ่ายเอกสาร ระบบดิจิตอล (ขาว-ดำ) ความเร็ว 40 แผ่นต่อนาที สำนักงานพัฒนาสังคมและความมั่นคงของมนุษย์จังหวัดน่าน ตำบลไชยสถาน อำเภอเมืองน่าน จังหวัดน่าน | F5: พมจ.น่าน | G5: น่าน | H5: 1 | I5: 0 | J5: =Table47[[#This Row],[ทดแทนจำนวน]]+Table47[[#This Row],[เพิ่มประสิทธิภาพจำนวน]] -> 1 | K5: 180000
A6: B000005 | B6: 2567 | C6: ครุภัณฑ์ | D6: สำนักงาน | E6: เครื่องถ่ายเอกสาร ระบบดิจิตอล (ขาว-ดำ) ความเร็ว 50 แผ่นต่อนาที สำนักงานพัฒนาสังคมและความมั่นคงของมนุษย์จังหวัดแพร่ ตำบลในเวียง อำเภอเมืองแพร่ จังหวัดแพร่ | F6: พมจ.แพร่ | G6: แพร่ | H6: 1 | I6: 0 | J6: =Table47[[#This Row],[ทดแทนจำนวน]]+Table47[[#This Row],[เพิ่มประสิทธิภาพจำนวน]] -> 1 | K6: 200000
A7: B000006 | B7: 2567 | C7: ครุภัณฑ์ | D7: ยานพาหนะและขนส่ง | E7: รถบรรทุก (ดีเซล) ขนาด 1 ตัน ปริมาตรกระบอกสูบไม่ต่ำกว่า 2,400 ซีซี หรือกำลังเครื่องยนต์สูงสุดไม่ต่ำกว่า 110 กิโลวัตต์ ขับเคลื่อน 2 ล้อ แบบดับเบิ้ลแค็บ พร้อมหลังคาไฟเบอร์กลาสหรือเหล็ก สำนักงานส่งเสริมและสนับสนุนวิชาการ 8 ตำบลผาเลือด อำเภอท่าปลา จังหวัดอุตรดิตถ์ | F7: สสว.8 | G7: อุตรดิษถ์ | H7: 1 | I7: 0 | J7: =Table47[[#This Row],[ทดแทนจำนวน]]+Table47[[#This Row],[เพิ่มประสิทธิภาพจำนวน]] -> 1 | K7: 885900
A8: B000007 | B8: 2567 | C8: ครุภัณฑ์ | D8: ยานพาหนะและขนส่ง | E8: รถบรรทุก (ดีเซล) ขนาด 1 ตัน ปริมาตรกระบอกสูบไม่ต่ำกว่า 2,400 ซีซี หรือกำลังเครื่องยนต์สูงสุดไม่ต่ำกว่า 110 กิโลวัตต์ ขับเคลื่อน 2 ล้อ แบบดับเบิ้ลแค็บ พร้อมหลังคาไฟเบอร์กลาสหรือเหล็ก สำนักงานพัฒนาสังคมและความมั่นคงของมนุษย์จังหวัดกาฬสินธุ์ ตำบลกาฬสินธุ์ อำเภอเมืองกาฬสินธุ์ จังหวัดกาฬสินธุ์ | F8: พมจ.กาฬสินธุ์ | G8: กาฬสินธุ์ | H8: 1 | I8: 0 | J8: =Table47[[#This Row],[ทดแทนจำนวน]]+Table47[[#This Row],[เพิ่มประสิทธิภาพจำนวน]] -> 1 | K8: 885900
A9: B000008 | B9: 2567 | C9: ครุภัณฑ์ | D9: ยานพาหนะและขนส่ง | E9: รถบรรทุก (ดีเซล) ขนาด 1 ตัน ปริมาตรกระบอกสูบไม่ต่ำกว่า 2,400 ซีซี หรือกำลังเครื่องยนต์สูงสุดไม่ต่ำกว่า 110 กิโลวัตต์ ขับเคลื่อน 4 ล้อ แบบดับเบิ้ลแค็บ พร้อมหลังคาไฟเบอร์กลาสหรือเหล็ก สำนักงานพัฒนาสังคมและความมั่นคงของมนุษย์จังหวัดกาฬสินธุ์ ตำบลกาฬสินธุ์ อำเภอเมืองกาฬสินธุ์ จังหวัดกาฬสินธุ์ | F9: พมจ.กาฬสินธุ์ | G9: กาฬสินธุ์ | H9: 1 | I9: 0 | J9: =Table47[[#This Row],[ทดแทนจำนวน]]+Table47[[#This Row],[เพิ่มประสิทธิภาพจำนวน]] -> 1 | K9: 1090900
A10: B000009 | B10: 2567 | C10: ครุภัณฑ์ | D10: สำนักงาน | E10: เครื่องถ่ายเอกสาร ระบบดิจิตอล (ขาว-ดำ) ความเร็ว 50 แผ่นต่อนาที สำนักงานพัฒนาสังคมและความมั่นคงของมนุษย์จังหวัดขอนแก่น ตำบลในเมือง อำเภอเมืองขอนแก่น จังหวัดขอนแก่น | F10: พมจ.ขอนแก่น | G10: ขอนแก่น | H10: 1 | I10: 0 | J10: =Table47[[#This Row],[ทดแทนจำนวน]]+Table47[[#This Row],[เพิ่มประสิทธิภาพจำนวน]] -> 1 | K10: 200000
A11: B000010 | B11: 2567 | C11: ครุภัณฑ์ | D11: ยานพาหนะและขนส่ง | E11: รถโดยสาร ขนาด 12 ที่นั่ง (ดีเซล) ปริมาตรกระบอกสูบไม่ต่ำกว่า 2,400 ซีซี หรือกำลังเครื่องยนต์สูงสุดไม่ต่ำกว่า 90 กิโลวัตต์ สำนักงานส่งเสริมและสนับสนุนวิชาการ 5 ตำบลโคกสูง อำเภออุบลรัตน์ จังหวัดขอนแก่น | F11: สสว.5 | G11: ขอนแก่น | H11: 1 | I11: 0 | J11: =Table47[[#This Row],[ทดแทนจำนวน]]+Table47[[#This Row],[เพิ่มประสิทธิภาพจำนวน]] -> 1 | K11: 1358000
A12: B000011 | B12: 2567 | C12: ครุภัณฑ์ | D12: ยานพาหนะและขนส่ง | E12: รถบรรทุก (ดีเซล) ขนาด 1 ตัน ปริมาตรกระบอกสูบไม่ต่ำกว่า 2,400 ซีซี หรือกำลังเครื่องยนต์สูงสุดไม่ต่ำกว่า 110 กิโลวัตต์ ขับเคลื่อน 4 ล้อ แบบดับเบิ้ลแค็บ พร้อมหลังคาไฟเบอร์กลาสหรือเหล็ก สำนักงานพัฒนาสังคมและความมั่นคงของมนุษย์จังหวัดชัยภูมิ ตำบลในเมือง อำเภอเมืองชัยภูมิ จังหวัดชัยภูมิ | F12: พมจ.ชัยภูมิ | G12: ชัยภูมิ | H12: 1 | I12: 0 | J12: =Table47[[#This Row],[ทดแทนจำนวน]]+Table47[[#This Row],[เพิ่มประสิทธิภาพจำนวน]] -> 1 | K12: 1090900
A13: B000012 | B13: 2567 | C13: ครุภัณฑ์ | D13: ยานพาหนะและขนส่ง | E13: รถโดยสาร ขนาด 12 ที่นั่ง (ดีเซล) ปริมาตรกระบอกสูบไม่ต่ำกว่า 2,400 ซีซี หรือกำลังเครื่องยนต์สูงสุดไม่ต่ำกว่า 90 กิโลวัตต์ สำนักงานพัฒนาสังคมและความมั่นคงของมนุษย์จังหวัดนครพนม ตำบลในเมือง อำเภอเมืองนครพนม จังหวัดนครพนม | F13: พมจ.นครพนม | G13: นครพนม | H13: 1 | I13: 0 | J13: =Table47[[#This Row],[ทดแทนจำนวน]]+Table47[[#This Row],[เพิ่มประสิทธิภาพจำนวน]] -> 1 | K13: 1358000
... A176: B000175 | B176: 2569 | C176: ครุภัณฑ์ | D176: สำนักงาน | E176: เครื่องปรับอากาศ แบบแยกส่วน แบบตั้งพื้นหรือแบบแขวน (ระบบ Inverter) ขนาด 36,000 บีทียู สำนักงานส่งเสริมและสนับสนุนวิชาการ 10 ตำบลขุนทะเล อำเภอเมืองสุราษฎร์ธานี จังหวัดสุราษฎร์ธานี | F176: สสว.10 | G176: สุราษฎร์ธานี | H176: 3 | I176: 0 | J176: =Table47[[#This Row],[ทดแทนจำนวน]]+Table47[[#This Row],[เพิ่มประสิทธิภาพจำนวน]] -> 3 | K176: 160800
A177: B000176 | B177: 2570 | C177: ครุภัณฑ์ | D177: ครุภัณฑ์ยานพาหนะและขนส่ง | E177: รถประจำตำแหน่ง ระดับอธิบดี รองปลัดกระทรวง เอกอัครราชทูตประจำกระทรวง ผู้ตรวจราชการกระทรวง รองเลขาธิการนายกรัฐมนตรีฝ่ายการเมือง เลขานุการรัฐมนตรี ผู้ช่วยเลขานุการรัฐมนตรี หรือผู้ดำรงตำแหน่งอื่นที่มีฐานะเทียบเท่า ปริมาตรกระบอกสูบไม่เกิน 2500 ซีซี หรือกำลังเครื่องยนต์สูงสุดไม่เกิน 160 กิโลวัตต์ หรือกำลังมอเตอร์ไฟฟ้าสูงสุดไม่เกิน 329 กิโลวัตต์ | F177: กก. | G177: กรุงเทพมหานคร | H177: 3 | I177: 0 | J177: =Table47[[#This Row],[ทดแทนจำนวน]]+Table47[[#This Row],[เพิ่มประสิทธิภาพจำนวน]] -> 3 | K177: 5028000 | L177: ทดแทนครุภัณฑ์เดิม
A178: B000177 | B178: 2570 | C178: ครุภัณฑ์ | D178: ครุภัณฑ์ยานพาหนะและขนส่ง | E178: รถโดยสารขนาด 12 ที่นั่ง (ดีเซล) ปริมาตรกระบอกสูบ ไม่ต่ำกว่า 2,400 ซีซี หรือกำลังเครื่องยนต์สูงสุดไม่ต่ำกว่า 90 กิโลวัตต์ | F178: กก. | G178: กรุงเทพมหานคร | H178: 2 | I178: 0 | J178: =Table47[[#This Row],[ทดแทนจำนวน]]+Table47[[#This Row],[เพิ่มประสิทธิภาพจำนวน]] -> 2 | K178: 2996000 | L178: ทดแทนครุภัณฑ์เดิม
A179: B000178 | B179: 2570 | C179: ครุภัณฑ์ | D179: ครุภัณฑ์ยานพาหนะและขนส่ง | E179: รถโดยสารขนาด 12 ที่นั่ง (ดีเซล) ปริมาตรกระบอกสูบ ไม่ต่ำกว่า 2,400 ซีซี หรือกำลังเครื่องยนต์สูงสุดไม่ต่ำกว่า 90 กิโลวัตต์ | F179: กก. | G179: กรุงเทพมหานคร | H179: 1 | I179: 0 | J179: =Table47[[#This Row],[ทดแทนจำนวน]]+Table47[[#This Row],[เพิ่มประสิทธิภาพจำนวน]] -> 1 | K179: 1498000 | L179: ทดแทนครุภัณฑ์เดิม
A180: B000179 | B180: 2570 | C180: ครุภัณฑ์ | D180: ครุภัณฑ์สำนักงาน | E180: เครื่องปรับอากาศ แบบติดผนัง ขนาด 18,000 บีทียู | F180: กก. | G180: กรุงเทพมหานคร | H180: 0 | I180: 8 | J180: =Table47[[#This Row],[ทดแทนจำนวน]]+Table47[[#This Row],[เพิ่มประสิทธิภาพจำนวน]] -> 8 | K180: 172000 | L180: เพิ่มประสิทธิภาพ
A181: B000180 | B181: 2570 | C181: ครุภัณฑ์ | D181: ครุภัณฑ์ยานพาหนะและขนส่ง | E181: รถโดยสารขนาด 12 ที่นั่ง (ดีเซล) ปริมาตรกระบอกสูบ ไม่ต่ำกว่า 2,400 ซีซี หรือกำลังเครื่องยนต์สูงสุดไม่ต่ำกว่า 90 กิโลวัตต์ | F181: กคม. | G181: กรุงเทพมหานคร | H181: 1 | I181: 0 | J181: =Table47[[#This Row],[ทดแทนจำนวน]]+Table47[[#This Row],[เพิ่มประสิทธิภาพจำนวน]] -> 1 | K181: 1498000 | L181: ทดแทนครุภัณฑ์เดิม
A182: B000181 | B182: 2570 | C182: ครุภัณฑ์ | D182: ครุภัณฑ์ยานพาหนะและขนส่ง | E182: รถโดยสารขนาด 12 ที่นั่ง (ดีเซล) ปริมาตรกระบอกสูบ ไม่ต่ำกว่า 2,400 ซีซี หรือกำลังเครื่องยนต์สูงสุดไม่ต่ำกว่า 90 กิโลวัตต์ | F182: กคม. | G182: กรุงเทพมหานคร | H182: 1 | I182: 0 | J182: =Table47[[#This Row],[ทดแทนจำนวน]]+Table47[[#This Row],[เพิ่มประสิทธิภาพจำนวน]] -> 1 | K182: 1498000 | L182: ทดแทนครุภัณฑ์เดิม
A183: B000182 | B183: 2570 | C183: ครุภัณฑ์ | D183: ครุภัณฑ์ยานพาหนะและขนส่ง | E183: รถโดยสารขนาด 12 ที่นั่ง (ดีเซล) ปริมาตรกระบอกสูบ ไม่ต่ำกว่า 2,400 ซีซี หรือกำลังเครื่องยนต์สูงสุดไม่ต่ำกว่า 90 กิโลวัตต์ | F183: กคม. | G183: กรุงเทพมหานคร | H183: 1 | I183: 0 | J183: =Table47[[#This Row],[ทดแทนจำนวน]]+Table47[[#This Row],[เพิ่มประสิทธิภาพจำนวน]] -> 1 | K183: 1498000 | L183: ทดแทนครุภัณฑ์เดิม
A184: B000183 | B184: 2570 | C184: ครุภัณฑ์ | D184: ครุภัณฑ์ยานพาหนะและขนส่ง | E184: รถบรรทุก (ดีเซล) ขนาด 1 ตัน ปริมาตรกระบอกสูบ ไม่ต่ำกว่า 2,400 ซีซี หรือกำลังเครื่องยนต์สูงสุดไม่ต่ำกว่า 110 กิโลวัตต์ ขับเคลื่อน 4 ล้อ แบบดับเบิ้ลแค็บ | F184: กคม. | G184: กรุงเทพมหานคร | H184: 1 | I184: 0 | J184: =Table47[[#This Row],[ทดแทนจำนวน]]+Table47[[#This Row],[เพิ่มประสิทธิภาพจำนวน]] -> 1 | K184: 1172000 | L184: ทดแทนครุภัณฑ์เดิม
A185: B000184 | B185: 2570 | C185: ครุภัณฑ์ | D185: ครุภัณฑ์ยานพาหนะและขนส่ง | E185: หลังคารถบรรทุก ขนาด 1 ตัน หลังคาไฟเบอร์กลาสหรือเหล็ก | F185: กคม. | G185: กรุงเทพมหานคร | H185: 1 | I185: 0 | J185: =Table47[[#This Row],[ทดแทนจำนวน]]+Table47[[#This Row],[เพิ่มประสิทธิภาพจำนวน]] -> 1 | K185: 35900 | L185: ทดแทนครุภัณฑ์เดิม
A186: B000185 | B186: 2570 | C186: ครุภัณฑ์ | D186: ครุภัณฑ์งานบ้านงานครัว | E186: เครื่องซักผ้าแบบธรรมดา ขนาด 15 กิโลกรัม | F186: สคม.ปทุมธานี | G186: ปทุมธานี | H186: 3 | I186: 0 | J186: =Table47[[#This Row],[ทดแทนจำนวน]]+Table47[[#This Row],[เพิ่มประสิทธิภาพจำนวน]] -> 3 | K186: 51000 | L186: ทดแทนครุภัณฑ์เดิม
A187: B000186 | B187: 2570 | C187: ครุภัณฑ์ | D187: ครุภัณฑ์งานบ้านงานครัว | E187: เครื่องตัดหญ้าแบบข้อแข็ง | F187: สคม.ปทุมธานี | G187: ปทุมธานี | H187: 0 | I187: 2 | J187: =Table47[[#This Row],[ทดแทนจำนวน]]+Table47[[#This Row],[เพิ่มประสิทธิภาพจำนวน]] -> 2 | K187: 19000 | L187: เพิ่มประสิทธิภาพ
A188: B000187 | B188: 2570 | C188: ครุภัณฑ์ | D188: ครุภัณฑ์งานบ้านงานครัว | E188: ปั๊มน้ำอัตโนมัติ ขนาด 200 วัตต์ | F188: สคม.ปทุมธานี | G188: ปทุมธานี | H188: 0 | I188: 8 | J188: =Table47[[#This Row],[ทดแทนจำนวน]]+Table47[[#This Row],[เพิ่มประสิทธิภาพจำนวน]] -> 8 | K188: 102400 | L188: เพิ่มประสิทธิภาพ
... A630: B000629 | B630: 2570 | C630: ครุภัณฑ์ | D630: ครุภัณฑ์โฆษณาและเผยแพร่ | E630: เครื่องมัลติมีเดียโปรเจคเตอร์ระดับ XGA ขนาด 5,000 ANSI Lumens | F630: สสว.10 | G630: สุราษฎร์ธานี | H630: 1 | I630: 0 | J630: =Table47[[#This Row],[ทดแทนจำนวน]]+Table47[[#This Row],[เพิ่มประสิทธิภาพจำนวน]] -> 1 | K630: 48600 | L630: ทดแทนครุภัณฑ์เดิม

Sheet รวมครุภัณฑ์ 70 (data)
A1: Column1 | B1: Column110 | C1: Column2 | D1: Column3 | E1: Column4 | F1: Column5 | G1: Column6 | H1: Column7 | I1: Column8 | J1: Column9 | K1: Column10 | L1: Column11 | M1: Column12 | N1: Column13 | O1: Column14 | P1: Column15 | Q1: Column16 | R1: Column17 | S1: Column18 | T1: Column19 | U1: Column20
A2: หมวด | B2: ปีงบประมาณ | C2: หมวดย่อย | D2: แผนงาน | E2: โครงการ | F2: กิจกรรม | G2: รายการ | H2: หน่วยงานที่ขอ | J2: จังหวัด | K2: ภาค | L2: คำขอ (บาท) | M2: คำขอ (รวมจำนวน) | N2: คำขอ (หน่วยนับ) | O2: ในมาตรฐาน | P2: นอกมาตรฐาน | Q2: คำขอ ทดแทน จำนวน | R2: คำขอ เพิ่ม ปสภ. จำนวน | S2: เลขครุภัณฑ์ทดแทน | T2: ราคา/หน่วย | U2: เหตุผล/ความจำเป็น
A3: ครุภัณฑ์ | B3: 2570 | C3: ครุภัณฑ์ยานพาหนะและขนส่ง | D3: ยุทธศาสตร์พัฒนาบริการประชาชนและพัฒนาประสิทธิภาพภาครัฐ | E3: ยกระดับองค์กรให้มีผลสัมฤทธิ์สูงสู่การเป็นองค์กรดิจิทัล | F3: พัฒนาองค์กรให้มีผลสัมฤทธิ์สูง | G3: รถประจำตำแหน่ง ระดับอธิบดี รองปลัดกระทรวง เอกอัครราชทูตประจำกระทรวง ผู้ตรวจราชการกระทรวง รองเลขาธิการนายกรัฐมนตรีฝ่ายการเมือง เลขานุการรัฐมนตรี ผู้ช่วยเลขานุการรัฐมนตรี หรือผู้ดำรงตำแหน่งอื่นที่มีฐานะเทียบเท่า ปริมาตรกระบอกสูบไม่เกิน 2500 ซีซี หรือกำลังเครื่องยนต์สูงสุดไม่เกิน 160 กิโลวัตต์ หรือกำลังมอเตอร์ไฟฟ้าสูงสุดไม่เกิน 329 กิโลวัตต์ | H3: กก. | J3: กรุงเทพมหานคร | K3: กลาง | L3: =M3*T3 -> 5028000 | M3: =Q3+R3 -> 3 | N3: คัน | Q3: 3 | S3: พม/สป-สบก(กอก)/05-01-02/001/2557 พม/สป-สบก(กอก)/05-01-02/002/2557 พม/สป-สบก(กอก)/05-01-02/003/2557 | T3: 1676000 | U3: ทดแทนหมายเลข พม/สป-สบก(กอก)/05-01-02/001/2557 พม/สป-สบก(กอก)/05-01-02/002/2557 พม/สป-สบก(กอก)/05-01-02/003/2557 ซึ่งมีอายุการใช้งาน 11 ปี หมดสภาพการใช้งาน ไม่สามารถใช้งานได้
A4: ครุภัณฑ์ | B4: 2570 | C4: ครุภัณฑ์ยานพาหนะและขนส่ง | D4: ยุทธศาสตร์พัฒนาบริการประชาชนและพัฒนาประสิทธิภาพภาครัฐ | E4: ยกระดับองค์กรให้มีผลสัมฤทธิ์สูงสู่การเป็นองค์กรดิจิทัล | F4: พัฒนาองค์กรให้มีผลสัมฤทธิ์สูง | G4: รถโดยสารขนาด 12 ที่นั่ง (ดีเซล) ปริมาตรกระบอกสูบ ไม่ต่ำกว่า 2,400 ซีซี หรือกำลังเครื่องยนต์สูงสุดไม่ต่ำกว่า 90 กิโลวัตต์ | H4: กก. | J4: กรุงเทพมหานคร | K4: กลาง | L4: =M4*T4 -> 2996000 | M4: =Q4+R4 -> 2 | N4: คัน | P4: P | Q4: 2 | S4: พม/สป-สบก(กอก)/05-01-03/002/2550 และ พม/สป-สบก(กอก)/05-01-03/003/2550 | T4: 1498000 | U4: ทดแทนหมายเลข พม/สป-สบก(กอก)/05-01-03/002/2550 และ พม/สป-สบก(กอก)/05-01-03/003/2550 ซึ่งมีอายุการใช้งาน 18 ปี หมดสภาพการใช้งาน อาจได้รับอันตรายกับเจ้าหน้าที่หากต้องเดินทางไปต่างจังหวัด และส่วนใหญ่ใช้ในการเดินทางไปราชการต่างจังหวัด
A5: ครุภัณฑ์ | B5: 2570 | C5: ครุภัณฑ์ยานพาหนะและขนส่ง | D5: ยุทธศาสตร์พัฒนาบริการประชาชนและพัฒนาประสิทธิภาพภาครัฐ | E5: ยกระดับองค์กรให้มีผลสัมฤทธิ์สูงสู่การเป็นองค์กรดิจิทัล | F5: พัฒนาองค์กรให้มีผลสัมฤทธิ์สูง | G5: รถโดยสารขนาด 12 ที่นั่ง (ดีเซล) ปริมาตรกระบอกสูบ ไม่ต่ำกว่า 2,400 ซีซี หรือกำลังเครื่องยนต์สูงสุดไม่ต่ำกว่า 90 กิโลวัตต์ | H5: กก. | J5: กรุงเทพมหานคร | K5: กลาง | L5: =M5*T5 -> 1498000 | M5: =Q5+R5 -> 1 | N5: คัน | P5: P | Q5: 1 | S5: พส/05-01-03/001/2549 | T5: 1498000 | U5: เนื่องจากรถยนต์ มีอายุการใช้งานนานกว่า 18 ปี วิ่งไปมากกว่า 500,000 กิโลเมตร มีอาการเสียระหว่างการเดินทางไปราชการบ่อย อะไหล่รถยนต์หายากไม่มีในประเทศไทย ทำให้รอตอนเวลาซ่อมนานไม่คุ้มกับค่าซ่อมแซม
A6: ครุภัณฑ์ | B6: 2570 | C6: ครุภัณฑ์สำนักงาน | D6: ยุทธศาสตร์พัฒนาบริการประชาชนและพัฒนาประสิทธิภาพภาครัฐ | E6: ยกระดับองค์กรให้มีผลสัมฤทธิ์สูงสู่การเป็นองค์กรดิจิทัล | F6: พัฒนาองค์กรให้มีผลสัมฤทธิ์สูง | G6: เครื่องปรับอากาศ แบบติดผนัง ขนาด 18,000 บีทียู | H6: กก. | J6: กรุงเทพมหานคร | K6: กลาง | L6: =M6*T6 -> 172000 | M6: =Q6+R6 -> 8 | N6: เครื่อง | O6: P | R6: 8 | T6: 21500 | U6: เนื่องจากเครื่องปรับอากาศ มีอายุการใช้งานนานกว่า 10 ปี หมดสภาพการใช้งาน ไม่คุ้มกับค่าซ่อมแซม เมื่อเปิดใช้งานในบางวันจะมีน้ำหยดออกมา มีแต่ลมร้อนออกจากตัวเครื่องปรับอากาศ
A7: ครุภัณฑ์ | B7: 2570 | C7: ครุภัณฑ์ยานพาหนะและขนส่ง | D7: ยุทธศาสตร์จัดการปัญหาแรงงานต่างด้าวและการค้ามนุษย์ | E7: ป้องกันและแก้ไขปัญหาการค้ามนุษย์ | F7: เพิ่มประสิทธิภาพระบบการคุ้มครองช่วยเหลือผู้เสียหายตาม กฏหมายและสอดคล้องกับหลักการสากล | G7: รถโดยสารขนาด 12 ที่นั่ง (ดีเซล) ปริมาตรกระบอกสูบ ไม่ต่ำกว่า 2,400 ซีซี หรือกำลังเครื่องยนต์สูงสุดไม่ต่ำกว่า 90 กิโลวัตต์ | H7: กคม. | J7: กรุงเทพมหานคร | K7: กลาง | L7: 1498000 | M7: 1 | N7: คัน | P7: P | Q7: 1 | S7: พส/สปป/05-01-03/007/2549 100000017855 | T7: 1498000 | U7: ขอทดแทน เนื่องจากรถมีอายุการใช้งานมาแล้ว 21 ปี ซึ่งไม่คุ้มค่ากัยการซ่อมแซมและบำรุงรักษา โดยใช้ในการปฏิบัติงาน ในภารกิจการคัดแยกผู้เสียหายจากการค้ามนุษย์ การติดตามเยี่ยมบ้านของผู้เสียหายรวมถึงเข้าร่วมภารกิจ เพื่อสนับสนุนกับทีมสหวิชาชีพให้การคุ้มครองช่วยเหลือในกรุงเทพฯ และต่างจังหวัดที่เกิดสถานการณ์
A8: ครุภัณฑ์ | B8: 2570 | C8: ครุภัณฑ์ยานพาหนะและขนส่ง | D8: ยุทธศาสตร์จัดการปัญหาแรงงานต่างด้าวและการค้ามนุษย์ | E8: ป้องกันและแก้ไขปัญหาการค้ามนุษย์ | F8: เพิ่มประสิทธิภาพระบบการคุ้มครองช่วยเหลือผู้เสียหายตาม กฏหมายและสอดคล้องกับหลักการสากล | G8: รถโดยสารขนาด 12 ที่นั่ง (ดีเซล) ปริมาตรกระบอกสูบ ไม่ต่ำกว่า 2,400 ซีซี หรือกำลังเครื่องยนต์สูงสุดไม่ต่ำกว่า 90 กิโลวัตต์ | H8: กคม. | J8: กรุงเทพมหานคร | K8: กลาง | L8: 1498000 | M8: 1 | N8: คัน | P8: P | Q8: 1 | S8: พส/สปป-สนย05-01-03/001/2552 100000008044 | T8: 1498000 | U8: ขอทดแทน เนื่องจากรถมีอายุการใช้งานมาแล้ว 18 ปี ซึ่งไม่คุ้มค่ากับการซ่อมแซมและบำรุงรักษา โดยใช้ในการปฏิบัติงาน ในภารกิจการคัดแยกผู้เสียหายจากการค้ามนุษย์ การติดตามเยี่ยมบ้านของผู้เสียหายรวมถึงเข้าร่วมภารกิจสนับสนุนกับทีมสหวิชาชีพให้การคุ้มครองช่วยเหลือในกรุงเทพฯ และต่างจังหวัดที่เกิดสถานการณ์
A9: ครุภัณฑ์ | B9: 2570 | C9: ครุภัณฑ์ยานพาหนะและขนส่ง | D9: ยุทธศาสตร์จัดการปัญหาแรงงานต่างด้าวและการค้ามนุษย์ | E9: ป้องกันและแก้ไขปัญหาการค้ามนุษย์ | F9: เพิ่มประสิทธิภาพระบบการคุ้มครองช่วยเหลือผู้เสียหายตาม กฏหมายและสอดคล้องกับหลักการสากล | G9: รถโดยสารขนาด 12 ที่นั่ง (ดีเซล) ปริมาตรกระบอกสูบ ไม่ต่ำกว่า 2,400 ซีซี หรือกำลังเครื่องยนต์สูงสุดไม่ต่ำกว่า 90 กิโลวัตต์ | H9: กคม. | J9: กรุงเทพมหานคร | K9: กลาง | L9: 1498000 | M9: 1 | N9: คัน | P9: P | Q9: 1 | S9: พส/สปป/05-01-03/001/2554 100000017874 | T9: 1498000 | U9: ขอทดแทน เนื่องจากรถมีอายุการใช้งานมาแล้ว 16 ปี ซึ่งไม่คุ้มค่ากับการซ่อมแซมและบำรุงรักษา โดยใช้ในการปฏิบัติงานในภารกิจการคัดแยกผู้เสียหายจากการค้ามนุษย์ การติดตามเยี่ยมบ้านของผู้เสียหายรวมถึงเข้าร่วมภารกิจสนับสนุนกับทีมสหวิชาชีพให้การคุ้มครองช่วยเหลือในกรุงเทพฯ และต่างจังหวัดที่เกิดสถานการณ์
A10: ครุภัณฑ์ | B10: 2570 | C10: ครุภัณฑ์ยานพาหนะและขนส่ง | D10: ยุทธศาสตร์จัดการปัญหาแรงงานต่างด้าวและการค้ามนุษย์ | E10: ป้องกันและแก้ไขปัญหาการค้ามนุษย์ | F10: เพิ่มประสิทธิภาพระบบการคุ้มครองช่วยเหลือผู้เสียหายตาม กฏหมายและสอดคล้องกับหลักการสากล | G10: รถบรรทุก (ดีเซล) ขนาด 1 ตัน ปริมาตรกระบอกสูบ ไม่ต่ำกว่า 2,400 ซีซี หรือกำลังเครื่องยนต์สูงสุดไม่ต่ำกว่า 110 กิโลวัตต์ ขับเคลื่อน 4 ล้อ แบบดับเบิ้ลแค็บ | H10: กคม. | J10: กรุงเทพมหานคร | K10: กลาง | L10: 1172000 | M10: 1 | N10: คัน | O10: P | Q10: 1 | S10: พส/สปป/05-01-04/001/2552 100000017872 | T10: 1172000 | U10: ขอทดแทน เนื่องจากรถมีอายุการใช้งานมาแล้ว 18 ปี ซึ่งไม่คุ้มค่ากับการซ่อมแซมและบำรุงรักษา โดยใช้ในการปฏิบัติงานในภารกิจการคัดแยกผู้เสียหายจากการค้ามนุษย์ การติดตามเยี่ยมบ้านของผู้เสียหายรวมถึงเข้าร่วมภารกิจสนับสนุนกับทีมสหวิชาชีพให้การคุ้มครองช่วยเหลือในกรุงเทพฯ และต่างจังหวัดที่เกิดสถานการณ์ ซึ่งมีพื้นที่ราบสูงและทุรกันดาร
A11: ครุภัณฑ์ | B11: 2570 | C11: ครุภัณฑ์ยานพาหนะและขนส่ง | D11: ยุทธศาสตร์จัดการปัญหาแรงงานต่างด้าวและการค้ามนุษย์ | E11: ป้องกันและแก้ไขปัญหาการค้ามนุษย์ | F11: เพิ่มประสิทธิภาพระบบการคุ้มครองช่วยเหลือผู้เสียหายตาม กฏหมายและสอดคล้องกับหลักการสากล | G11: หลังคารถบรรทุก ขนาด 1 ตัน หลังคาไฟเบอร์กลาสหรือเหล็ก | H11: กคม. | J11: กรุงเทพมหานคร | K11: กลาง | L11: 35900 | M11: 1 | N11: หลัง | O11: P | Q11: 1 | S11: 100000017871 | T11: 35900 | U11: ขอทดแทน เนื่องจากเป็นหลังคาที่ติดตั้งกับรถบรรทุก ขนาด 1 ตัน ซึ่งมีอายุการใช้งานมาแล้ว 18 ปี และเสื่อมสภาพจากการใช้งาน
A12: ครุภัณฑ์ | B12: 2570 | C12: ครุภัณฑ์งานบ้านงานครัว | D12: ยุทธศาสตร์จัดการปัญหาแรงงานต่างด้าวและการค้ามนุษย์ | E12: ป้องกันและแก้ไขปัญหาการค้ามนุษย์ | F12: เพิ่มประสิทธิภาพระบบการคุ้มครองช่วยเหลือผู้เสียหายตาม กฏหมายและสอดคล้องกับหลักการสากล | G12: เครื่องซักผ้าแบบธรรมดา ขนาด 15 กิโลกรัม | H12: สคม.ปทุมธานี | J12: ปทุมธานี | K12: กลาง | L12: 51000 | M12: 3 | N12: เครื่อง | O12: P | Q12: 3 | S12: เลขหลัก GFMIS 100000022059 100000022060 100000022061 | T12: 17000 | U12: ขอทดแทน เนื่องจากหน่วยงานมีความจำเป็นต้องใช้เครื่องซักผ้า สำหรับซักทำความสะอาดเสื้อผ้า เครื่องนอน ของผู้เสียหายที่อยู่ภายในสถานคุ้มครอง ซึ่งมีความต้องการใช้เป็นประจำทุกวัน เพื่อรักษาความสะอาดและสุขอนามัยที่เหมาะสม
A13: ครุภัณฑ์ | B13: 2570 | C13: ครุภัณฑ์งานบ้านงานครัว | D13: ยุทธศาสตร์จัดการปัญหาแรงงานต่างด้าวและการค้ามนุษย์ | E13: ป้องกันและแก้ไขปัญหาการค้ามนุษย์ | F13: เพิ่มประสิทธิภาพระบบการคุ้มครองช่วยเหลือผู้เสียหายตาม กฏหมายและสอดคล้องกับหลักการสากล | G13: เครื่องตัดหญ้าแบบข้อแข็ง | H13: สคม.ปทุมธานี | J13: ปทุมธานี | K13: กลาง | L13: 19000 | M13: 2 | N13: เครื่อง | O13: P | T13: 9500 | U13: ขอเพิ่มประสิทธิภาพ เนื่องจากหน่วยงานมีภารกิจในการดูแลพื้นที่ภายในสถานที่ราชการ ซึ่งมีบริเวณกว้างและมีหญ้าขึ้นเป็นจำนวนมาก จำเป็นต้องมีการตัดแต่งและบำรุงรักษาอย่างต่อเนื่อง เพื่อให้สถานที่มีความสะอาด เป็นระเบียบเรียบร้อย และเกิดภาพลักษณ์ที่เหมาะสมกับการเป็นสถานที่ราชการ ปัจจุบัน หน่วยงานมีเครื่องตัดหญ้าไม่เพียงพอต่อการใช้งานจริง ส่งผลให้การดูแลพื้นที่โดยรอบไม่ทั่วถึงและล่าช้า เพื่อให้การบำรุงรักษาความสะอาดของบริเวณสถานที่ราชการเป็นไปอย่างต่อเนื่อง และสามารถดำเนินการได้อย่างมีประสิทธิภาพ
A14: ครุภัณฑ์ | B14: 2570 | C14: ครุภัณฑ์งานบ้านงานครัว | D14: ยุทธศาสตร์จัดการปัญหาแรงงานต่างด้าวและการค้ามนุษย์ | E14: ป้องกันและแก้ไขปัญหาการค้ามนุษย์ | F14: เพิ่มประสิทธิภาพระบบการคุ้มครองช่วยเหลือผู้เสียหายตาม กฏหมายและสอดคล้องกับหลักการสากล | G14: ปั๊มน้ำอัตโนมัติ ขนาด 200 วัตต์ | H14: สคม.ปทุมธานี | J14: ปทุมธานี | K14: กลาง | L14: 102400 | M14: 8 | N14: เครื่อง | P14: P | R14: 8 | T14: 12800 | U14: ขอเพิ่มประสิทธิภาพ เนื่องจากหน่วยงานมีความจำเป็นต้องใช้น้ำเพื่ออุปโภคและบริโภคในหลายส่วน ทั้งในส่วนของผู้เสียหายที่พักอาศัยอยู่ภายในสถานที่ เจ้าหน้าที่ผู้ปฏิบัติงาน ตลอดจนประชาชนที่มาติดต่อราชการ โดยมีการใช้น้ำในปริมาณมากและอย่างต่อเนื่องทุกวัน อย่างไรก็ตาม หน่วยงานยังไม่เคยได้รับการจัดสรรปั๊มน้ำ มาก่อน ส่งผลให้การจ่ายน้ำไม่เพียงพอต่อความต้องการ โดยเฉพาะในช่วงเวลาที่มีการใช้น้ำพร้อมกันหลายจุด ซึ่งทำให้แรงดันน้ำลดลง ไม่สามารถส่งน้ำขึ้นถังเก็บน้ำได้ทั่วถึง และอาจกระทบต่อความเป็นอยู่ของผู้เสียหายรวมถึงประสิทธิภาพในการดำเนินงานของเจ้าหน้าที่
A15: ครุภัณฑ์ | B15: 2570 | C15: ครุภัณฑ์สำนักงาน | D15: ยุทธศาสตร์จัดการปัญหาแรงงานต่างด้าวและการค้ามนุษย์ | E15: ป้องกันและแก้ไขปัญหาการค้ามนุษย์ | F15: เพิ่มประสิทธิภาพระบบการคุ้มครองช่วยเหลือผู้เสียหายตาม กฏหมายและสอดคล้องกับหลักการสากล | G15: เครื่องปรับอากาศ แบบแยกส่วน แบบตั้งพื้นหรือแบบแขวน ระบบ (Inverter) ขนาด 30,000 บีทียู | H15: สคม.ปทุมธานี | J15: ปทุมธานี | K15: กลาง | L15: 236000 | M15: 5 | N15: เครื่อง | O15: P | Q15: 5 | S15: พส/สปป-04/04-07-01/02/2554 , พส/สปป-04/04-07-01/03/2554, พส/สปป-04/04-07-01/01/2557 , พส/สปป-04/04-07-01/02/2557 , พส/สปป-04/04-07-01/03/2557 | T15: 47200 | U15: ขอทดแทน 1. ห้องประชุมอาคาร 16 จำนวน 2 เครื่อง (ใช้จัดประชุมประจำเดือน และต้อนรับหน่วยงานต่างๆ รวมถึงคณะผู้มาเยี่ยมเยียน) 2. อาคารศูนย์ปฏิบัติการ จำนวน 2 เครื่อง (ใช้จัดงานต้อนรับ หรือต้อนรับแขกผู้มาติดต่อจากหน่วยงานภายนอก) 3. อาคาร 20 ชั้น 1 กลุ่มส่งเสริมและพัฒนา 1 เครื่อง
A16: ครุภัณฑ์ | B16: 2570 | C16: ครุภัณฑ์ยานพาหนะและขนส่ง | D16: ยุทธศาสตร์จัดการปัญหาแรงงานต่างด้าวและการค้ามนุษย์ | E16: ป้องกันและแก้ไขปัญหาการค้ามนุษย์ | F16: เพิ่มประสิทธิภาพระบบการคุ้มครองช่วยเหลือผู้เสียหายตาม กฏหมายและสอดคล้องกับหลักการสากล | G16: รถยนต์โดยสารขนาด 12 ที่นั่ง เครื่องยนต์ดีเซล ปริมาณกระบอกสูบไม่ต่ำกว่า 2,400 ซีซี หรือกำลังเครื่องยนต์สูงสุดไม่ต่ำกว่า 90 กิโลวัตต์ | H16: สคม.ปทุมธานี | J16: ปทุมธานี | K16: กลาง | L16: 1329000 | M16: 1 | N16: คัน | P16: P | Q16: 1 | S16: พส/สปป-04/5-01-03/01/2554(100000019486) ทะเบียน นค 5006 ปทุมธานี | T16: 1329000 | U16: ขอทดแทน เนื่องจากหน่วยงานมีความจำเป็นต้องใช้รถยนต์โดยสารขนาด 12 ที่นั่ง ในการรับ-ส่งผู้เสียหายฯไปสืบพยานที่ศาล ไปโรงพยาบาล ติดตามเยี่ยมบ้านผู้เสียหายฯ ภายในประเทศเป็นประจำทุกเดือนและส่งกลับภูมิลำเนา ซึ่งบางกรณีต้องเดินทางไปส่งยังประเทศต้นทาง ตามด่านชายแดนจังหวัดต่างๆ เยี่ยมเยียนผู้เสียหายที่ออกไปทำงานภายนอก ตลอดจนการติดต่อประสานงานกับหน่วยงานอื่นที่เกี่ยวข้อง
